[
    {
        "additional_details": null,
        "exception": "Failed to describe EC2 VPC: An error occurred (AuthFailure) when calling the DescribeVpcs operation: AWS was not able to validate the provided access credentials",
        "file": "ec2.py",
        "line": 65,
        "traceback": "Traceback (most recent call last):\n  File \"c:\\Go\\ScoutSuite\\ScoutSuite\\providers\\aws\\facade\\ec2.py\", line 65, in get_vpcs\n    return await run_concurrently(lambda: ec2_client.describe_vpcs()['Vpcs'])\n  File \"C:\\Python37\\lib\\concurrent\\futures\\thread.py\", line 57, in run\n    result = self.fn(*self.args, **self.kwargs)\n  File \"c:\\Go\\ScoutSuite\\ScoutSuite\\providers\\aws\\facade\\ec2.py\", line 65, in <lambda>\n    return await run_concurrently(lambda: ec2_client.describe_vpcs()['Vpcs'])\n  File \"C:\\Python37\\lib\\site-packages\\botocore\\client.py\", line 357, in _api_call\n    return self._make_api_call(operation_name, kwargs)\n  File \"C:\\Python37\\lib\\site-packages\\botocore\\client.py\", line 661, in _make_api_call\n    raise error_class(parsed_response, operation_name)\nbotocore.exceptions.ClientError: An error occurred (AuthFailure) when calling the DescribeVpcs operation: AWS was not able to validate the provided access credentials\n"
    },
    {
        "additional_details": null,
        "exception": "Failed to get EC2 images: An error occurred (AuthFailure) when calling the DescribeImages operation: AWS was not able to validate the provided access credentials",
        "file": "ec2.py",
        "line": 74,
        "traceback": "Traceback (most recent call last):\n  File \"c:\\Go\\ScoutSuite\\ScoutSuite\\providers\\aws\\facade\\ec2.py\", line 74, in get_images\n    return await run_concurrently(lambda: client.describe_images(Filters=filters)['Images'])\n  File \"C:\\Python37\\lib\\concurrent\\futures\\thread.py\", line 57, in run\n    result = self.fn(*self.args, **self.kwargs)\n  File \"c:\\Go\\ScoutSuite\\ScoutSuite\\providers\\aws\\facade\\ec2.py\", line 74, in <lambda>\n    return await run_concurrently(lambda: client.describe_images(Filters=filters)['Images'])\n  File \"C:\\Python37\\lib\\site-packages\\botocore\\client.py\", line 357, in _api_call\n    return self._make_api_call(operation_name, kwargs)\n  File \"C:\\Python37\\lib\\site-packages\\botocore\\client.py\", line 661, in _make_api_call\n    raise error_class(parsed_response, operation_name)\nbotocore.exceptions.ClientError: An error occurred (AuthFailure) when calling the DescribeImages operation: AWS was not able to validate the provided access credentials\n"
    },
    {
        "additional_details": null,
        "exception": "Failed to get EC2 volumes: An error occurred (AuthFailure) when calling the DescribeVolumes operation: AWS was not able to validate the provided access credentials",
        "file": "ec2.py",
        "line": 90,
        "traceback": "Traceback (most recent call last):\n  File \"c:\\Go\\ScoutSuite\\ScoutSuite\\providers\\aws\\facade\\ec2.py\", line 90, in get_volumes\n    volumes = await AWSFacadeUtils.get_all_pages('ec2', region, self.session, 'describe_volumes', 'Volumes')\n  File \"c:\\Go\\ScoutSuite\\ScoutSuite\\providers\\aws\\facade\\utils.py\", line 28, in get_all_pages\n    service, region, session, paginator_name, [entity], **paginator_args)\n  File \"c:\\Go\\ScoutSuite\\ScoutSuite\\providers\\aws\\facade\\utils.py\", line 58, in get_multiple_entities_from_all_pages\n    return await run_concurrently(lambda: AWSFacadeUtils._get_all_pages_from_paginator(paginator, entities))\n  File \"C:\\Python37\\lib\\concurrent\\futures\\thread.py\", line 57, in run\n    result = self.fn(*self.args, **self.kwargs)\n  File \"c:\\Go\\ScoutSuite\\ScoutSuite\\providers\\aws\\facade\\utils.py\", line 58, in <lambda>\n    return await run_concurrently(lambda: AWSFacadeUtils._get_all_pages_from_paginator(paginator, entities))\n  File \"c:\\Go\\ScoutSuite\\ScoutSuite\\providers\\aws\\facade\\utils.py\", line 74, in _get_all_pages_from_paginator\n    for page in paginator:\n  File \"C:\\Python37\\lib\\site-packages\\botocore\\paginate.py\", line 255, in __iter__\n    response = self._make_request(current_kwargs)\n  File \"C:\\Python37\\lib\\site-packages\\botocore\\paginate.py\", line 332, in _make_request\n    return self._method(**current_kwargs)\n  File \"C:\\Python37\\lib\\site-packages\\botocore\\client.py\", line 357, in _api_call\n    return self._make_api_call(operation_name, kwargs)\n  File \"C:\\Python37\\lib\\site-packages\\botocore\\client.py\", line 661, in _make_api_call\n    raise error_class(parsed_response, operation_name)\nbotocore.exceptions.ClientError: An error occurred (AuthFailure) when calling the DescribeVolumes operation: AWS was not able to validate the provided access credentials\n"
    },
    {
        "additional_details": null,
        "exception": "Failed to describe CloutTrail trail: An error occurred (UnrecognizedClientException) when calling the DescribeTrails operation: The security token included in the request is invalid.",
        "file": "cloudtrail.py",
        "line": 13,
        "traceback": "Traceback (most recent call last):\n  File \"c:\\Go\\ScoutSuite\\ScoutSuite\\providers\\aws\\facade\\cloudtrail.py\", line 13, in get_trails\n    lambda: client.describe_trails()['trailList'])\n  File \"C:\\Python37\\lib\\concurrent\\futures\\thread.py\", line 57, in run\n    result = self.fn(*self.args, **self.kwargs)\n  File \"c:\\Go\\ScoutSuite\\ScoutSuite\\providers\\aws\\facade\\cloudtrail.py\", line 13, in <lambda>\n    lambda: client.describe_trails()['trailList'])\n  File \"C:\\Python37\\lib\\site-packages\\botocore\\client.py\", line 357, in _api_call\n    return self._make_api_call(operation_name, kwargs)\n  File \"C:\\Python37\\lib\\site-packages\\botocore\\client.py\", line 661, in _make_api_call\n    raise error_class(parsed_response, operation_name)\nbotocore.exceptions.ClientError: An error occurred (UnrecognizedClientException) when calling the DescribeTrails operation: The security token included in the request is invalid.\n"
    },
    {
        "additional_details": null,
        "exception": "Failed to get Config recorders: An error occurred (UnrecognizedClientException) when calling the DescribeConfigurationRecorders operation: The security token included in the request is invalid.",
        "file": "config.py",
        "line": 17,
        "traceback": "Traceback (most recent call last):\n  File \"c:\\Go\\ScoutSuite\\ScoutSuite\\providers\\aws\\facade\\config.py\", line 17, in get_recorders\n    recorders = (await run_concurrently(client.describe_configuration_recorders))['ConfigurationRecorders']\n  File \"C:\\Python37\\lib\\concurrent\\futures\\thread.py\", line 57, in run\n    result = self.fn(*self.args, **self.kwargs)\n  File \"C:\\Python37\\lib\\site-packages\\botocore\\client.py\", line 357, in _api_call\n    return self._make_api_call(operation_name, kwargs)\n  File \"C:\\Python37\\lib\\site-packages\\botocore\\client.py\", line 661, in _make_api_call\n    raise error_class(parsed_response, operation_name)\nbotocore.exceptions.ClientError: An error occurred (UnrecognizedClientException) when calling the DescribeConfigurationRecorders operation: The security token included in the request is invalid.\n"
    },
    {
        "additional_details": null,
        "exception": "Failed to describe EC2 VPC: An error occurred (AuthFailure) when calling the DescribeVpcs operation: AWS was not able to validate the provided access credentials",
        "file": "ec2.py",
        "line": 65,
        "traceback": "Traceback (most recent call last):\n  File \"c:\\Go\\ScoutSuite\\ScoutSuite\\providers\\aws\\facade\\ec2.py\", line 65, in get_vpcs\n    return await run_concurrently(lambda: ec2_client.describe_vpcs()['Vpcs'])\n  File \"C:\\Python37\\lib\\concurrent\\futures\\thread.py\", line 57, in run\n    result = self.fn(*self.args, **self.kwargs)\n  File \"c:\\Go\\ScoutSuite\\ScoutSuite\\providers\\aws\\facade\\ec2.py\", line 65, in <lambda>\n    return await run_concurrently(lambda: ec2_client.describe_vpcs()['Vpcs'])\n  File \"C:\\Python37\\lib\\site-packages\\botocore\\client.py\", line 357, in _api_call\n    return self._make_api_call(operation_name, kwargs)\n  File \"C:\\Python37\\lib\\site-packages\\botocore\\client.py\", line 661, in _make_api_call\n    raise error_class(parsed_response, operation_name)\nbotocore.exceptions.ClientError: An error occurred (AuthFailure) when calling the DescribeVpcs operation: AWS was not able to validate the provided access credentials\n"
    },
    {
        "additional_details": null,
        "exception": "Failed to describe EC2 VPC: An error occurred (AuthFailure) when calling the DescribeVpcs operation: AWS was not able to validate the provided access credentials",
        "file": "ec2.py",
        "line": 65,
        "traceback": "Traceback (most recent call last):\n  File \"c:\\Go\\ScoutSuite\\ScoutSuite\\providers\\aws\\facade\\ec2.py\", line 65, in get_vpcs\n    return await run_concurrently(lambda: ec2_client.describe_vpcs()['Vpcs'])\n  File \"C:\\Python37\\lib\\concurrent\\futures\\thread.py\", line 57, in run\n    result = self.fn(*self.args, **self.kwargs)\n  File \"c:\\Go\\ScoutSuite\\ScoutSuite\\providers\\aws\\facade\\ec2.py\", line 65, in <lambda>\n    return await run_concurrently(lambda: ec2_client.describe_vpcs()['Vpcs'])\n  File \"C:\\Python37\\lib\\site-packages\\botocore\\client.py\", line 357, in _api_call\n    return self._make_api_call(operation_name, kwargs)\n  File \"C:\\Python37\\lib\\site-packages\\botocore\\client.py\", line 661, in _make_api_call\n    raise error_class(parsed_response, operation_name)\nbotocore.exceptions.ClientError: An error occurred (AuthFailure) when calling the DescribeVpcs operation: AWS was not able to validate the provided access credentials\n"
    },
    {
        "additional_details": null,
        "exception": "Failed to get ElastiCache security groups: An error occurred (InvalidClientTokenId) when calling the DescribeCacheSecurityGroups operation: The security token included in the request is invalid.",
        "file": "elasticache.py",
        "line": 48,
        "traceback": "Traceback (most recent call last):\n  File \"c:\\Go\\ScoutSuite\\ScoutSuite\\providers\\aws\\facade\\elasticache.py\", line 48, in get_security_groups\n    'elasticache', region, self.session, 'describe_cache_security_groups', 'CacheSecurityGroups')\n  File \"c:\\Go\\ScoutSuite\\ScoutSuite\\providers\\aws\\facade\\utils.py\", line 28, in get_all_pages\n    service, region, session, paginator_name, [entity], **paginator_args)\n  File \"c:\\Go\\ScoutSuite\\ScoutSuite\\providers\\aws\\facade\\utils.py\", line 58, in get_multiple_entities_from_all_pages\n    return await run_concurrently(lambda: AWSFacadeUtils._get_all_pages_from_paginator(paginator, entities))\n  File \"C:\\Python37\\lib\\concurrent\\futures\\thread.py\", line 57, in run\n    result = self.fn(*self.args, **self.kwargs)\n  File \"c:\\Go\\ScoutSuite\\ScoutSuite\\providers\\aws\\facade\\utils.py\", line 58, in <lambda>\n    return await run_concurrently(lambda: AWSFacadeUtils._get_all_pages_from_paginator(paginator, entities))\n  File \"c:\\Go\\ScoutSuite\\ScoutSuite\\providers\\aws\\facade\\utils.py\", line 74, in _get_all_pages_from_paginator\n    for page in paginator:\n  File \"C:\\Python37\\lib\\site-packages\\botocore\\paginate.py\", line 255, in __iter__\n    response = self._make_request(current_kwargs)\n  File \"C:\\Python37\\lib\\site-packages\\botocore\\paginate.py\", line 332, in _make_request\n    return self._method(**current_kwargs)\n  File \"C:\\Python37\\lib\\site-packages\\botocore\\client.py\", line 357, in _api_call\n    return self._make_api_call(operation_name, kwargs)\n  File \"C:\\Python37\\lib\\site-packages\\botocore\\client.py\", line 661, in _make_api_call\n    raise error_class(parsed_response, operation_name)\nbotocore.exceptions.ClientError: An error occurred (InvalidClientTokenId) when calling the DescribeCacheSecurityGroups operation: The security token included in the request is invalid.\n"
    },
    {
        "additional_details": null,
        "exception": "Failed to describe cache parameter groups: An error occurred (InvalidClientTokenId) when calling the DescribeCacheParameterGroups operation: The security token included in the request is invalid.",
        "file": "elasticache.py",
        "line": 80,
        "traceback": "Traceback (most recent call last):\n  File \"c:\\Go\\ScoutSuite\\ScoutSuite\\providers\\aws\\facade\\elasticache.py\", line 80, in get_parameter_groups\n    'elasticache', region, self.session, 'describe_cache_parameter_groups', 'CacheParameterGroups')\n  File \"c:\\Go\\ScoutSuite\\ScoutSuite\\providers\\aws\\facade\\utils.py\", line 28, in get_all_pages\n    service, region, session, paginator_name, [entity], **paginator_args)\n  File \"c:\\Go\\ScoutSuite\\ScoutSuite\\providers\\aws\\facade\\utils.py\", line 58, in get_multiple_entities_from_all_pages\n    return await run_concurrently(lambda: AWSFacadeUtils._get_all_pages_from_paginator(paginator, entities))\n  File \"C:\\Python37\\lib\\concurrent\\futures\\thread.py\", line 57, in run\n    result = self.fn(*self.args, **self.kwargs)\n  File \"c:\\Go\\ScoutSuite\\ScoutSuite\\providers\\aws\\facade\\utils.py\", line 58, in <lambda>\n    return await run_concurrently(lambda: AWSFacadeUtils._get_all_pages_from_paginator(paginator, entities))\n  File \"c:\\Go\\ScoutSuite\\ScoutSuite\\providers\\aws\\facade\\utils.py\", line 74, in _get_all_pages_from_paginator\n    for page in paginator:\n  File \"C:\\Python37\\lib\\site-packages\\botocore\\paginate.py\", line 255, in __iter__\n    response = self._make_request(current_kwargs)\n  File \"C:\\Python37\\lib\\site-packages\\botocore\\paginate.py\", line 332, in _make_request\n    return self._method(**current_kwargs)\n  File \"C:\\Python37\\lib\\site-packages\\botocore\\client.py\", line 357, in _api_call\n    return self._make_api_call(operation_name, kwargs)\n  File \"C:\\Python37\\lib\\site-packages\\botocore\\client.py\", line 661, in _make_api_call\n    raise error_class(parsed_response, operation_name)\nbotocore.exceptions.ClientError: An error occurred (InvalidClientTokenId) when calling the DescribeCacheParameterGroups operation: The security token included in the request is invalid.\n"
    },
    {
        "additional_details": null,
        "exception": "Failed to describe EC2 VPC: An error occurred (AuthFailure) when calling the DescribeVpcs operation: AWS was not able to validate the provided access credentials",
        "file": "ec2.py",
        "line": 65,
        "traceback": "Traceback (most recent call last):\n  File \"c:\\Go\\ScoutSuite\\ScoutSuite\\providers\\aws\\facade\\ec2.py\", line 65, in get_vpcs\n    return await run_concurrently(lambda: ec2_client.describe_vpcs()['Vpcs'])\n  File \"C:\\Python37\\lib\\concurrent\\futures\\thread.py\", line 57, in run\n    result = self.fn(*self.args, **self.kwargs)\n  File \"c:\\Go\\ScoutSuite\\ScoutSuite\\providers\\aws\\facade\\ec2.py\", line 65, in <lambda>\n    return await run_concurrently(lambda: ec2_client.describe_vpcs()['Vpcs'])\n  File \"C:\\Python37\\lib\\site-packages\\botocore\\client.py\", line 357, in _api_call\n    return self._make_api_call(operation_name, kwargs)\n  File \"C:\\Python37\\lib\\site-packages\\botocore\\client.py\", line 661, in _make_api_call\n    raise error_class(parsed_response, operation_name)\nbotocore.exceptions.ClientError: An error occurred (AuthFailure) when calling the DescribeVpcs operation: AWS was not able to validate the provided access credentials\n"
    },
    {
        "additional_details": null,
        "exception": "Failed to get peering connections: An error occurred (AuthFailure) when calling the DescribeVpcPeeringConnections operation: AWS was not able to validate the provided access credentials",
        "file": "ec2.py",
        "line": 173,
        "traceback": "Traceback (most recent call last):\n  File \"c:\\Go\\ScoutSuite\\ScoutSuite\\providers\\aws\\facade\\ec2.py\", line 173, in get_peering_connections\n    peering_connections = await AWSFacadeUtils.get_all_pages('ec2', region, self.session, 'describe_vpc_peering_connections', 'VpcPeeringConnections')\n  File \"c:\\Go\\ScoutSuite\\ScoutSuite\\providers\\aws\\facade\\utils.py\", line 28, in get_all_pages\n    service, region, session, paginator_name, [entity], **paginator_args)\n  File \"c:\\Go\\ScoutSuite\\ScoutSuite\\providers\\aws\\facade\\utils.py\", line 58, in get_multiple_entities_from_all_pages\n    return await run_concurrently(lambda: AWSFacadeUtils._get_all_pages_from_paginator(paginator, entities))\n  File \"C:\\Python37\\lib\\concurrent\\futures\\thread.py\", line 57, in run\n    result = self.fn(*self.args, **self.kwargs)\n  File \"c:\\Go\\ScoutSuite\\ScoutSuite\\providers\\aws\\facade\\utils.py\", line 58, in <lambda>\n    return await run_concurrently(lambda: AWSFacadeUtils._get_all_pages_from_paginator(paginator, entities))\n  File \"c:\\Go\\ScoutSuite\\ScoutSuite\\providers\\aws\\facade\\utils.py\", line 74, in _get_all_pages_from_paginator\n    for page in paginator:\n  File \"C:\\Python37\\lib\\site-packages\\botocore\\paginate.py\", line 255, in __iter__\n    response = self._make_request(current_kwargs)\n  File \"C:\\Python37\\lib\\site-packages\\botocore\\paginate.py\", line 332, in _make_request\n    return self._method(**current_kwargs)\n  File \"C:\\Python37\\lib\\site-packages\\botocore\\client.py\", line 357, in _api_call\n    return self._make_api_call(operation_name, kwargs)\n  File \"C:\\Python37\\lib\\site-packages\\botocore\\client.py\", line 661, in _make_api_call\n    raise error_class(parsed_response, operation_name)\nbotocore.exceptions.ClientError: An error occurred (AuthFailure) when calling the DescribeVpcPeeringConnections operation: AWS was not able to validate the provided access credentials\n"
    },
    {
        "additional_details": null,
        "exception": "Failed to get EC2 flow logs: An error occurred (AuthFailure) when calling the DescribeFlowLogs operation: AWS was not able to validate the provided access credentials",
        "file": "ec2.py",
        "line": 139,
        "traceback": "Traceback (most recent call last):\n  File \"c:\\Go\\ScoutSuite\\ScoutSuite\\providers\\aws\\facade\\ec2.py\", line 139, in get_flow_logs\n    await self.cache_flow_logs(region)\n  File \"c:\\Go\\ScoutSuite\\ScoutSuite\\providers\\aws\\facade\\ec2.py\", line 151, in cache_flow_logs\n    await AWSFacadeUtils.get_all_pages('ec2', region, self.session, 'describe_flow_logs', 'FlowLogs')\n  File \"c:\\Go\\ScoutSuite\\ScoutSuite\\providers\\aws\\facade\\utils.py\", line 28, in get_all_pages\n    service, region, session, paginator_name, [entity], **paginator_args)\n  File \"c:\\Go\\ScoutSuite\\ScoutSuite\\providers\\aws\\facade\\utils.py\", line 58, in get_multiple_entities_from_all_pages\n    return await run_concurrently(lambda: AWSFacadeUtils._get_all_pages_from_paginator(paginator, entities))\n  File \"C:\\Python37\\lib\\concurrent\\futures\\thread.py\", line 57, in run\n    result = self.fn(*self.args, **self.kwargs)\n  File \"c:\\Go\\ScoutSuite\\ScoutSuite\\providers\\aws\\facade\\utils.py\", line 58, in <lambda>\n    return await run_concurrently(lambda: AWSFacadeUtils._get_all_pages_from_paginator(paginator, entities))\n  File \"c:\\Go\\ScoutSuite\\ScoutSuite\\providers\\aws\\facade\\utils.py\", line 74, in _get_all_pages_from_paginator\n    for page in paginator:\n  File \"C:\\Python37\\lib\\site-packages\\botocore\\paginate.py\", line 255, in __iter__\n    response = self._make_request(current_kwargs)\n  File \"C:\\Python37\\lib\\site-packages\\botocore\\paginate.py\", line 332, in _make_request\n    return self._method(**current_kwargs)\n  File \"C:\\Python37\\lib\\site-packages\\botocore\\client.py\", line 357, in _api_call\n    return self._make_api_call(operation_name, kwargs)\n  File \"C:\\Python37\\lib\\site-packages\\botocore\\client.py\", line 661, in _make_api_call\n    raise error_class(parsed_response, operation_name)\nbotocore.exceptions.ClientError: An error occurred (AuthFailure) when calling the DescribeFlowLogs operation: AWS was not able to validate the provided access credentials\n"
    },
    {
        "additional_details": null,
        "exception": "Failed to describe EC2 VPC: An error occurred (AuthFailure) when calling the DescribeVpcs operation: AWS was not able to validate the provided access credentials",
        "file": "ec2.py",
        "line": 65,
        "traceback": "Traceback (most recent call last):\n  File \"c:\\Go\\ScoutSuite\\ScoutSuite\\providers\\aws\\facade\\ec2.py\", line 65, in get_vpcs\n    return await run_concurrently(lambda: ec2_client.describe_vpcs()['Vpcs'])\n  File \"C:\\Python37\\lib\\concurrent\\futures\\thread.py\", line 57, in run\n    result = self.fn(*self.args, **self.kwargs)\n  File \"c:\\Go\\ScoutSuite\\ScoutSuite\\providers\\aws\\facade\\ec2.py\", line 65, in <lambda>\n    return await run_concurrently(lambda: ec2_client.describe_vpcs()['Vpcs'])\n  File \"C:\\Python37\\lib\\site-packages\\botocore\\client.py\", line 357, in _api_call\n    return self._make_api_call(operation_name, kwargs)\n  File \"C:\\Python37\\lib\\site-packages\\botocore\\client.py\", line 661, in _make_api_call\n    raise error_class(parsed_response, operation_name)\nbotocore.exceptions.ClientError: An error occurred (AuthFailure) when calling the DescribeVpcs operation: AWS was not able to validate the provided access credentials\n"
    },
    {
        "additional_details": null,
        "exception": "Failed to describe cluster security groups: An error occurred (InvalidClientTokenId) when calling the DescribeClusterSecurityGroups operation: The security token included in the request is invalid.",
        "file": "redshift.py",
        "line": 39,
        "traceback": "Traceback (most recent call last):\n  File \"c:\\Go\\ScoutSuite\\ScoutSuite\\providers\\aws\\facade\\redshift.py\", line 39, in get_cluster_security_groups\n    'redshift', region, self.session, 'describe_cluster_security_groups', 'ClusterSecurityGroups')\n  File \"c:\\Go\\ScoutSuite\\ScoutSuite\\providers\\aws\\facade\\utils.py\", line 28, in get_all_pages\n    service, region, session, paginator_name, [entity], **paginator_args)\n  File \"c:\\Go\\ScoutSuite\\ScoutSuite\\providers\\aws\\facade\\utils.py\", line 58, in get_multiple_entities_from_all_pages\n    return await run_concurrently(lambda: AWSFacadeUtils._get_all_pages_from_paginator(paginator, entities))\n  File \"C:\\Python37\\lib\\concurrent\\futures\\thread.py\", line 57, in run\n    result = self.fn(*self.args, **self.kwargs)\n  File \"c:\\Go\\ScoutSuite\\ScoutSuite\\providers\\aws\\facade\\utils.py\", line 58, in <lambda>\n    return await run_concurrently(lambda: AWSFacadeUtils._get_all_pages_from_paginator(paginator, entities))\n  File \"c:\\Go\\ScoutSuite\\ScoutSuite\\providers\\aws\\facade\\utils.py\", line 74, in _get_all_pages_from_paginator\n    for page in paginator:\n  File \"C:\\Python37\\lib\\site-packages\\botocore\\paginate.py\", line 255, in __iter__\n    response = self._make_request(current_kwargs)\n  File \"C:\\Python37\\lib\\site-packages\\botocore\\paginate.py\", line 332, in _make_request\n    return self._method(**current_kwargs)\n  File \"C:\\Python37\\lib\\site-packages\\botocore\\client.py\", line 357, in _api_call\n    return self._make_api_call(operation_name, kwargs)\n  File \"C:\\Python37\\lib\\site-packages\\botocore\\client.py\", line 661, in _make_api_call\n    raise error_class(parsed_response, operation_name)\nbotocore.exceptions.ClientError: An error occurred (InvalidClientTokenId) when calling the DescribeClusterSecurityGroups operation: The security token included in the request is invalid.\n"
    },
    {
        "additional_details": null,
        "exception": "Failed to describe EC2 VPC: An error occurred (AuthFailure) when calling the DescribeVpcs operation: AWS was not able to validate the provided access credentials",
        "file": "ec2.py",
        "line": 65,
        "traceback": "Traceback (most recent call last):\n  File \"c:\\Go\\ScoutSuite\\ScoutSuite\\providers\\aws\\facade\\ec2.py\", line 65, in get_vpcs\n    return await run_concurrently(lambda: ec2_client.describe_vpcs()['Vpcs'])\n  File \"C:\\Python37\\lib\\concurrent\\futures\\thread.py\", line 57, in run\n    result = self.fn(*self.args, **self.kwargs)\n  File \"c:\\Go\\ScoutSuite\\ScoutSuite\\providers\\aws\\facade\\ec2.py\", line 65, in <lambda>\n    return await run_concurrently(lambda: ec2_client.describe_vpcs()['Vpcs'])\n  File \"C:\\Python37\\lib\\site-packages\\botocore\\client.py\", line 357, in _api_call\n    return self._make_api_call(operation_name, kwargs)\n  File \"C:\\Python37\\lib\\site-packages\\botocore\\client.py\", line 661, in _make_api_call\n    raise error_class(parsed_response, operation_name)\nbotocore.exceptions.ClientError: An error occurred (AuthFailure) when calling the DescribeVpcs operation: AWS was not able to validate the provided access credentials\n"
    },
    {
        "additional_details": null,
        "exception": "Failed to list SQS queues: An error occurred (InvalidClientTokenId) when calling the ListQueues operation: The security token included in the request is invalid.",
        "file": "sqs.py",
        "line": 11,
        "traceback": "Traceback (most recent call last):\n  File \"c:\\Go\\ScoutSuite\\ScoutSuite\\providers\\aws\\facade\\sqs.py\", line 11, in get_queues\n    raw_queues = await run_concurrently(sqs_client.list_queues)\n  File \"C:\\Python37\\lib\\concurrent\\futures\\thread.py\", line 57, in run\n    result = self.fn(*self.args, **self.kwargs)\n  File \"C:\\Python37\\lib\\site-packages\\botocore\\client.py\", line 357, in _api_call\n    return self._make_api_call(operation_name, kwargs)\n  File \"C:\\Python37\\lib\\site-packages\\botocore\\client.py\", line 661, in _make_api_call\n    raise error_class(parsed_response, operation_name)\nbotocore.exceptions.ClientError: An error occurred (InvalidClientTokenId) when calling the ListQueues operation: The security token included in the request is invalid.\n"
    },
    {
        "additional_details": null,
        "exception": "Failed to describe EC2 VPC: An error occurred (AuthFailure) when calling the DescribeVpcs operation: AWS was not able to validate the provided access credentials",
        "file": "ec2.py",
        "line": 65,
        "traceback": "Traceback (most recent call last):\n  File \"c:\\Go\\ScoutSuite\\ScoutSuite\\providers\\aws\\facade\\ec2.py\", line 65, in get_vpcs\n    return await run_concurrently(lambda: ec2_client.describe_vpcs()['Vpcs'])\n  File \"C:\\Python37\\lib\\concurrent\\futures\\thread.py\", line 57, in run\n    result = self.fn(*self.args, **self.kwargs)\n  File \"c:\\Go\\ScoutSuite\\ScoutSuite\\providers\\aws\\facade\\ec2.py\", line 65, in <lambda>\n    return await run_concurrently(lambda: ec2_client.describe_vpcs()['Vpcs'])\n  File \"C:\\Python37\\lib\\site-packages\\botocore\\client.py\", line 357, in _api_call\n    return self._make_api_call(operation_name, kwargs)\n  File \"C:\\Python37\\lib\\site-packages\\botocore\\client.py\", line 661, in _make_api_call\n    raise error_class(parsed_response, operation_name)\nbotocore.exceptions.ClientError: An error occurred (AuthFailure) when calling the DescribeVpcs operation: AWS was not able to validate the provided access credentials\n"
    },
    {
        "additional_details": null,
        "exception": "Failed to describe EC2 snapshot attributes: An error occurred (RequestLimitExceeded) when calling the DescribeSnapshotAttribute operation (reached max retries: 4): Request limit exceeded.",
        "file": "ec2.py",
        "line": 121,
        "traceback": "Traceback (most recent call last):\n  File \"c:\\Go\\ScoutSuite\\ScoutSuite\\providers\\aws\\facade\\ec2.py\", line 121, in _get_and_set_snapshot_attributes\n    snapshot['CreateVolumePermissions'] = await run_concurrently(lambda: ec2_client.describe_snapshot_attribute(\n  File \"C:\\Python37\\lib\\concurrent\\futures\\thread.py\", line 57, in run\n    result = self.fn(*self.args, **self.kwargs)\n  File \"c:\\Go\\ScoutSuite\\ScoutSuite\\providers\\aws\\facade\\ec2.py\", line 123, in <lambda>\n    SnapshotId=snapshot['SnapshotId'])['CreateVolumePermissions'])\n  File \"C:\\Python37\\lib\\site-packages\\botocore\\client.py\", line 357, in _api_call\n    return self._make_api_call(operation_name, kwargs)\n  File \"C:\\Python37\\lib\\site-packages\\botocore\\client.py\", line 661, in _make_api_call\n    raise error_class(parsed_response, operation_name)\nbotocore.exceptions.ClientError: An error occurred (RequestLimitExceeded) when calling the DescribeSnapshotAttribute operation (reached max retries: 4): Request limit exceeded.\n"
    },
    {
        "additional_details": null,
        "exception": "Failed to describe EC2 snapshot attributes: An error occurred (RequestLimitExceeded) when calling the DescribeSnapshotAttribute operation (reached max retries: 4): Request limit exceeded.",
        "file": "ec2.py",
        "line": 121,
        "traceback": "Traceback (most recent call last):\n  File \"c:\\Go\\ScoutSuite\\ScoutSuite\\providers\\aws\\facade\\ec2.py\", line 121, in _get_and_set_snapshot_attributes\n    snapshot['CreateVolumePermissions'] = await run_concurrently(lambda: ec2_client.describe_snapshot_attribute(\n  File \"C:\\Python37\\lib\\concurrent\\futures\\thread.py\", line 57, in run\n    result = self.fn(*self.args, **self.kwargs)\n  File \"c:\\Go\\ScoutSuite\\ScoutSuite\\providers\\aws\\facade\\ec2.py\", line 123, in <lambda>\n    SnapshotId=snapshot['SnapshotId'])['CreateVolumePermissions'])\n  File \"C:\\Python37\\lib\\site-packages\\botocore\\client.py\", line 357, in _api_call\n    return self._make_api_call(operation_name, kwargs)\n  File \"C:\\Python37\\lib\\site-packages\\botocore\\client.py\", line 661, in _make_api_call\n    raise error_class(parsed_response, operation_name)\nbotocore.exceptions.ClientError: An error occurred (RequestLimitExceeded) when calling the DescribeSnapshotAttribute operation (reached max retries: 4): Request limit exceeded.\n"
    },
    {
        "additional_details": null,
        "exception": "Failed to describe EC2 snapshot attributes: An error occurred (RequestLimitExceeded) when calling the DescribeSnapshotAttribute operation (reached max retries: 4): Request limit exceeded.",
        "file": "ec2.py",
        "line": 121,
        "traceback": "Traceback (most recent call last):\n  File \"c:\\Go\\ScoutSuite\\ScoutSuite\\providers\\aws\\facade\\ec2.py\", line 121, in _get_and_set_snapshot_attributes\n    snapshot['CreateVolumePermissions'] = await run_concurrently(lambda: ec2_client.describe_snapshot_attribute(\n  File \"C:\\Python37\\lib\\concurrent\\futures\\thread.py\", line 57, in run\n    result = self.fn(*self.args, **self.kwargs)\n  File \"c:\\Go\\ScoutSuite\\ScoutSuite\\providers\\aws\\facade\\ec2.py\", line 123, in <lambda>\n    SnapshotId=snapshot['SnapshotId'])['CreateVolumePermissions'])\n  File \"C:\\Python37\\lib\\site-packages\\botocore\\client.py\", line 357, in _api_call\n    return self._make_api_call(operation_name, kwargs)\n  File \"C:\\Python37\\lib\\site-packages\\botocore\\client.py\", line 661, in _make_api_call\n    raise error_class(parsed_response, operation_name)\nbotocore.exceptions.ClientError: An error occurred (RequestLimitExceeded) when calling the DescribeSnapshotAttribute operation (reached max retries: 4): Request limit exceeded.\n"
    },
    {
        "additional_details": null,
        "exception": "Failed to describe EC2 snapshot attributes: An error occurred (RequestLimitExceeded) when calling the DescribeSnapshotAttribute operation (reached max retries: 4): Request limit exceeded.",
        "file": "ec2.py",
        "line": 121,
        "traceback": "Traceback (most recent call last):\n  File \"c:\\Go\\ScoutSuite\\ScoutSuite\\providers\\aws\\facade\\ec2.py\", line 121, in _get_and_set_snapshot_attributes\n    snapshot['CreateVolumePermissions'] = await run_concurrently(lambda: ec2_client.describe_snapshot_attribute(\n  File \"C:\\Python37\\lib\\concurrent\\futures\\thread.py\", line 57, in run\n    result = self.fn(*self.args, **self.kwargs)\n  File \"c:\\Go\\ScoutSuite\\ScoutSuite\\providers\\aws\\facade\\ec2.py\", line 123, in <lambda>\n    SnapshotId=snapshot['SnapshotId'])['CreateVolumePermissions'])\n  File \"C:\\Python37\\lib\\site-packages\\botocore\\client.py\", line 357, in _api_call\n    return self._make_api_call(operation_name, kwargs)\n  File \"C:\\Python37\\lib\\site-packages\\botocore\\client.py\", line 661, in _make_api_call\n    raise error_class(parsed_response, operation_name)\nbotocore.exceptions.ClientError: An error occurred (RequestLimitExceeded) when calling the DescribeSnapshotAttribute operation (reached max retries: 4): Request limit exceeded.\n"
    },
    {
        "additional_details": null,
        "exception": "Failed to describe EC2 snapshot attributes: An error occurred (RequestLimitExceeded) when calling the DescribeSnapshotAttribute operation (reached max retries: 4): Request limit exceeded.",
        "file": "ec2.py",
        "line": 121,
        "traceback": "Traceback (most recent call last):\n  File \"c:\\Go\\ScoutSuite\\ScoutSuite\\providers\\aws\\facade\\ec2.py\", line 121, in _get_and_set_snapshot_attributes\n    snapshot['CreateVolumePermissions'] = await run_concurrently(lambda: ec2_client.describe_snapshot_attribute(\n  File \"C:\\Python37\\lib\\concurrent\\futures\\thread.py\", line 57, in run\n    result = self.fn(*self.args, **self.kwargs)\n  File \"c:\\Go\\ScoutSuite\\ScoutSuite\\providers\\aws\\facade\\ec2.py\", line 123, in <lambda>\n    SnapshotId=snapshot['SnapshotId'])['CreateVolumePermissions'])\n  File \"C:\\Python37\\lib\\site-packages\\botocore\\client.py\", line 357, in _api_call\n    return self._make_api_call(operation_name, kwargs)\n  File \"C:\\Python37\\lib\\site-packages\\botocore\\client.py\", line 661, in _make_api_call\n    raise error_class(parsed_response, operation_name)\nbotocore.exceptions.ClientError: An error occurred (RequestLimitExceeded) when calling the DescribeSnapshotAttribute operation (reached max retries: 4): Request limit exceeded.\n"
    },
    {
        "additional_details": null,
        "exception": "Failed to describe EC2 snapshot attributes: An error occurred (RequestLimitExceeded) when calling the DescribeSnapshotAttribute operation (reached max retries: 4): Request limit exceeded.",
        "file": "ec2.py",
        "line": 121,
        "traceback": "Traceback (most recent call last):\n  File \"c:\\Go\\ScoutSuite\\ScoutSuite\\providers\\aws\\facade\\ec2.py\", line 121, in _get_and_set_snapshot_attributes\n    snapshot['CreateVolumePermissions'] = await run_concurrently(lambda: ec2_client.describe_snapshot_attribute(\n  File \"C:\\Python37\\lib\\concurrent\\futures\\thread.py\", line 57, in run\n    result = self.fn(*self.args, **self.kwargs)\n  File \"c:\\Go\\ScoutSuite\\ScoutSuite\\providers\\aws\\facade\\ec2.py\", line 123, in <lambda>\n    SnapshotId=snapshot['SnapshotId'])['CreateVolumePermissions'])\n  File \"C:\\Python37\\lib\\site-packages\\botocore\\client.py\", line 357, in _api_call\n    return self._make_api_call(operation_name, kwargs)\n  File \"C:\\Python37\\lib\\site-packages\\botocore\\client.py\", line 661, in _make_api_call\n    raise error_class(parsed_response, operation_name)\nbotocore.exceptions.ClientError: An error occurred (RequestLimitExceeded) when calling the DescribeSnapshotAttribute operation (reached max retries: 4): Request limit exceeded.\n"
    },
    {
        "additional_details": null,
        "exception": "Failed to describe EC2 snapshot attributes: An error occurred (RequestLimitExceeded) when calling the DescribeSnapshotAttribute operation (reached max retries: 4): Request limit exceeded.",
        "file": "ec2.py",
        "line": 121,
        "traceback": "Traceback (most recent call last):\n  File \"c:\\Go\\ScoutSuite\\ScoutSuite\\providers\\aws\\facade\\ec2.py\", line 121, in _get_and_set_snapshot_attributes\n    snapshot['CreateVolumePermissions'] = await run_concurrently(lambda: ec2_client.describe_snapshot_attribute(\n  File \"C:\\Python37\\lib\\concurrent\\futures\\thread.py\", line 57, in run\n    result = self.fn(*self.args, **self.kwargs)\n  File \"c:\\Go\\ScoutSuite\\ScoutSuite\\providers\\aws\\facade\\ec2.py\", line 123, in <lambda>\n    SnapshotId=snapshot['SnapshotId'])['CreateVolumePermissions'])\n  File \"C:\\Python37\\lib\\site-packages\\botocore\\client.py\", line 357, in _api_call\n    return self._make_api_call(operation_name, kwargs)\n  File \"C:\\Python37\\lib\\site-packages\\botocore\\client.py\", line 661, in _make_api_call\n    raise error_class(parsed_response, operation_name)\nbotocore.exceptions.ClientError: An error occurred (RequestLimitExceeded) when calling the DescribeSnapshotAttribute operation (reached max retries: 4): Request limit exceeded.\n"
    },
    {
        "additional_details": null,
        "exception": "Failed to describe EC2 snapshot attributes: An error occurred (RequestLimitExceeded) when calling the DescribeSnapshotAttribute operation (reached max retries: 4): Request limit exceeded.",
        "file": "ec2.py",
        "line": 121,
        "traceback": "Traceback (most recent call last):\n  File \"c:\\Go\\ScoutSuite\\ScoutSuite\\providers\\aws\\facade\\ec2.py\", line 121, in _get_and_set_snapshot_attributes\n    snapshot['CreateVolumePermissions'] = await run_concurrently(lambda: ec2_client.describe_snapshot_attribute(\n  File \"C:\\Python37\\lib\\concurrent\\futures\\thread.py\", line 57, in run\n    result = self.fn(*self.args, **self.kwargs)\n  File \"c:\\Go\\ScoutSuite\\ScoutSuite\\providers\\aws\\facade\\ec2.py\", line 123, in <lambda>\n    SnapshotId=snapshot['SnapshotId'])['CreateVolumePermissions'])\n  File \"C:\\Python37\\lib\\site-packages\\botocore\\client.py\", line 357, in _api_call\n    return self._make_api_call(operation_name, kwargs)\n  File \"C:\\Python37\\lib\\site-packages\\botocore\\client.py\", line 661, in _make_api_call\n    raise error_class(parsed_response, operation_name)\nbotocore.exceptions.ClientError: An error occurred (RequestLimitExceeded) when calling the DescribeSnapshotAttribute operation (reached max retries: 4): Request limit exceeded.\n"
    },
    {
        "additional_details": null,
        "exception": "Failed to describe EC2 snapshot attributes: An error occurred (RequestLimitExceeded) when calling the DescribeSnapshotAttribute operation (reached max retries: 4): Request limit exceeded.",
        "file": "ec2.py",
        "line": 121,
        "traceback": "Traceback (most recent call last):\n  File \"c:\\Go\\ScoutSuite\\ScoutSuite\\providers\\aws\\facade\\ec2.py\", line 121, in _get_and_set_snapshot_attributes\n    snapshot['CreateVolumePermissions'] = await run_concurrently(lambda: ec2_client.describe_snapshot_attribute(\n  File \"C:\\Python37\\lib\\concurrent\\futures\\thread.py\", line 57, in run\n    result = self.fn(*self.args, **self.kwargs)\n  File \"c:\\Go\\ScoutSuite\\ScoutSuite\\providers\\aws\\facade\\ec2.py\", line 123, in <lambda>\n    SnapshotId=snapshot['SnapshotId'])['CreateVolumePermissions'])\n  File \"C:\\Python37\\lib\\site-packages\\botocore\\client.py\", line 357, in _api_call\n    return self._make_api_call(operation_name, kwargs)\n  File \"C:\\Python37\\lib\\site-packages\\botocore\\client.py\", line 661, in _make_api_call\n    raise error_class(parsed_response, operation_name)\nbotocore.exceptions.ClientError: An error occurred (RequestLimitExceeded) when calling the DescribeSnapshotAttribute operation (reached max retries: 4): Request limit exceeded.\n"
    },
    {
        "additional_details": null,
        "exception": "Failed to describe EC2 snapshot attributes: An error occurred (RequestLimitExceeded) when calling the DescribeSnapshotAttribute operation (reached max retries: 4): Request limit exceeded.",
        "file": "ec2.py",
        "line": 121,
        "traceback": "Traceback (most recent call last):\n  File \"c:\\Go\\ScoutSuite\\ScoutSuite\\providers\\aws\\facade\\ec2.py\", line 121, in _get_and_set_snapshot_attributes\n    snapshot['CreateVolumePermissions'] = await run_concurrently(lambda: ec2_client.describe_snapshot_attribute(\n  File \"C:\\Python37\\lib\\concurrent\\futures\\thread.py\", line 57, in run\n    result = self.fn(*self.args, **self.kwargs)\n  File \"c:\\Go\\ScoutSuite\\ScoutSuite\\providers\\aws\\facade\\ec2.py\", line 123, in <lambda>\n    SnapshotId=snapshot['SnapshotId'])['CreateVolumePermissions'])\n  File \"C:\\Python37\\lib\\site-packages\\botocore\\client.py\", line 357, in _api_call\n    return self._make_api_call(operation_name, kwargs)\n  File \"C:\\Python37\\lib\\site-packages\\botocore\\client.py\", line 661, in _make_api_call\n    raise error_class(parsed_response, operation_name)\nbotocore.exceptions.ClientError: An error occurred (RequestLimitExceeded) when calling the DescribeSnapshotAttribute operation (reached max retries: 4): Request limit exceeded.\n"
    },
    {
        "additional_details": null,
        "exception": "Failed to describe EC2 snapshot attributes: An error occurred (RequestLimitExceeded) when calling the DescribeSnapshotAttribute operation (reached max retries: 4): Request limit exceeded.",
        "file": "ec2.py",
        "line": 121,
        "traceback": "Traceback (most recent call last):\n  File \"c:\\Go\\ScoutSuite\\ScoutSuite\\providers\\aws\\facade\\ec2.py\", line 121, in _get_and_set_snapshot_attributes\n    snapshot['CreateVolumePermissions'] = await run_concurrently(lambda: ec2_client.describe_snapshot_attribute(\n  File \"C:\\Python37\\lib\\concurrent\\futures\\thread.py\", line 57, in run\n    result = self.fn(*self.args, **self.kwargs)\n  File \"c:\\Go\\ScoutSuite\\ScoutSuite\\providers\\aws\\facade\\ec2.py\", line 123, in <lambda>\n    SnapshotId=snapshot['SnapshotId'])['CreateVolumePermissions'])\n  File \"C:\\Python37\\lib\\site-packages\\botocore\\client.py\", line 357, in _api_call\n    return self._make_api_call(operation_name, kwargs)\n  File \"C:\\Python37\\lib\\site-packages\\botocore\\client.py\", line 661, in _make_api_call\n    raise error_class(parsed_response, operation_name)\nbotocore.exceptions.ClientError: An error occurred (RequestLimitExceeded) when calling the DescribeSnapshotAttribute operation (reached max retries: 4): Request limit exceeded.\n"
    },
    {
        "additional_details": null,
        "exception": "Failed to describe EC2 snapshot attributes: An error occurred (RequestLimitExceeded) when calling the DescribeSnapshotAttribute operation (reached max retries: 4): Request limit exceeded.",
        "file": "ec2.py",
        "line": 121,
        "traceback": "Traceback (most recent call last):\n  File \"c:\\Go\\ScoutSuite\\ScoutSuite\\providers\\aws\\facade\\ec2.py\", line 121, in _get_and_set_snapshot_attributes\n    snapshot['CreateVolumePermissions'] = await run_concurrently(lambda: ec2_client.describe_snapshot_attribute(\n  File \"C:\\Python37\\lib\\concurrent\\futures\\thread.py\", line 57, in run\n    result = self.fn(*self.args, **self.kwargs)\n  File \"c:\\Go\\ScoutSuite\\ScoutSuite\\providers\\aws\\facade\\ec2.py\", line 123, in <lambda>\n    SnapshotId=snapshot['SnapshotId'])['CreateVolumePermissions'])\n  File \"C:\\Python37\\lib\\site-packages\\botocore\\client.py\", line 357, in _api_call\n    return self._make_api_call(operation_name, kwargs)\n  File \"C:\\Python37\\lib\\site-packages\\botocore\\client.py\", line 661, in _make_api_call\n    raise error_class(parsed_response, operation_name)\nbotocore.exceptions.ClientError: An error occurred (RequestLimitExceeded) when calling the DescribeSnapshotAttribute operation (reached max retries: 4): Request limit exceeded.\n"
    },
    {
        "additional_details": null,
        "exception": "Failed to describe EC2 snapshot attributes: An error occurred (RequestLimitExceeded) when calling the DescribeSnapshotAttribute operation (reached max retries: 4): Request limit exceeded.",
        "file": "ec2.py",
        "line": 121,
        "traceback": "Traceback (most recent call last):\n  File \"c:\\Go\\ScoutSuite\\ScoutSuite\\providers\\aws\\facade\\ec2.py\", line 121, in _get_and_set_snapshot_attributes\n    snapshot['CreateVolumePermissions'] = await run_concurrently(lambda: ec2_client.describe_snapshot_attribute(\n  File \"C:\\Python37\\lib\\concurrent\\futures\\thread.py\", line 57, in run\n    result = self.fn(*self.args, **self.kwargs)\n  File \"c:\\Go\\ScoutSuite\\ScoutSuite\\providers\\aws\\facade\\ec2.py\", line 123, in <lambda>\n    SnapshotId=snapshot['SnapshotId'])['CreateVolumePermissions'])\n  File \"C:\\Python37\\lib\\site-packages\\botocore\\client.py\", line 357, in _api_call\n    return self._make_api_call(operation_name, kwargs)\n  File \"C:\\Python37\\lib\\site-packages\\botocore\\client.py\", line 661, in _make_api_call\n    raise error_class(parsed_response, operation_name)\nbotocore.exceptions.ClientError: An error occurred (RequestLimitExceeded) when calling the DescribeSnapshotAttribute operation (reached max retries: 4): Request limit exceeded.\n"
    },
    {
        "additional_details": null,
        "exception": "Failed to describe EC2 snapshot attributes: An error occurred (RequestLimitExceeded) when calling the DescribeSnapshotAttribute operation (reached max retries: 4): Request limit exceeded.",
        "file": "ec2.py",
        "line": 121,
        "traceback": "Traceback (most recent call last):\n  File \"c:\\Go\\ScoutSuite\\ScoutSuite\\providers\\aws\\facade\\ec2.py\", line 121, in _get_and_set_snapshot_attributes\n    snapshot['CreateVolumePermissions'] = await run_concurrently(lambda: ec2_client.describe_snapshot_attribute(\n  File \"C:\\Python37\\lib\\concurrent\\futures\\thread.py\", line 57, in run\n    result = self.fn(*self.args, **self.kwargs)\n  File \"c:\\Go\\ScoutSuite\\ScoutSuite\\providers\\aws\\facade\\ec2.py\", line 123, in <lambda>\n    SnapshotId=snapshot['SnapshotId'])['CreateVolumePermissions'])\n  File \"C:\\Python37\\lib\\site-packages\\botocore\\client.py\", line 357, in _api_call\n    return self._make_api_call(operation_name, kwargs)\n  File \"C:\\Python37\\lib\\site-packages\\botocore\\client.py\", line 661, in _make_api_call\n    raise error_class(parsed_response, operation_name)\nbotocore.exceptions.ClientError: An error occurred (RequestLimitExceeded) when calling the DescribeSnapshotAttribute operation (reached max retries: 4): Request limit exceeded.\n"
    },
    {
        "additional_details": null,
        "exception": "Failed to describe EC2 snapshot attributes: An error occurred (RequestLimitExceeded) when calling the DescribeSnapshotAttribute operation (reached max retries: 4): Request limit exceeded.",
        "file": "ec2.py",
        "line": 121,
        "traceback": "Traceback (most recent call last):\n  File \"c:\\Go\\ScoutSuite\\ScoutSuite\\providers\\aws\\facade\\ec2.py\", line 121, in _get_and_set_snapshot_attributes\n    snapshot['CreateVolumePermissions'] = await run_concurrently(lambda: ec2_client.describe_snapshot_attribute(\n  File \"C:\\Python37\\lib\\concurrent\\futures\\thread.py\", line 57, in run\n    result = self.fn(*self.args, **self.kwargs)\n  File \"c:\\Go\\ScoutSuite\\ScoutSuite\\providers\\aws\\facade\\ec2.py\", line 123, in <lambda>\n    SnapshotId=snapshot['SnapshotId'])['CreateVolumePermissions'])\n  File \"C:\\Python37\\lib\\site-packages\\botocore\\client.py\", line 357, in _api_call\n    return self._make_api_call(operation_name, kwargs)\n  File \"C:\\Python37\\lib\\site-packages\\botocore\\client.py\", line 661, in _make_api_call\n    raise error_class(parsed_response, operation_name)\nbotocore.exceptions.ClientError: An error occurred (RequestLimitExceeded) when calling the DescribeSnapshotAttribute operation (reached max retries: 4): Request limit exceeded.\n"
    },
    {
        "additional_details": null,
        "exception": "Failed to describe EC2 snapshot attributes: An error occurred (RequestLimitExceeded) when calling the DescribeSnapshotAttribute operation (reached max retries: 4): Request limit exceeded.",
        "file": "ec2.py",
        "line": 121,
        "traceback": "Traceback (most recent call last):\n  File \"c:\\Go\\ScoutSuite\\ScoutSuite\\providers\\aws\\facade\\ec2.py\", line 121, in _get_and_set_snapshot_attributes\n    snapshot['CreateVolumePermissions'] = await run_concurrently(lambda: ec2_client.describe_snapshot_attribute(\n  File \"C:\\Python37\\lib\\concurrent\\futures\\thread.py\", line 57, in run\n    result = self.fn(*self.args, **self.kwargs)\n  File \"c:\\Go\\ScoutSuite\\ScoutSuite\\providers\\aws\\facade\\ec2.py\", line 123, in <lambda>\n    SnapshotId=snapshot['SnapshotId'])['CreateVolumePermissions'])\n  File \"C:\\Python37\\lib\\site-packages\\botocore\\client.py\", line 357, in _api_call\n    return self._make_api_call(operation_name, kwargs)\n  File \"C:\\Python37\\lib\\site-packages\\botocore\\client.py\", line 661, in _make_api_call\n    raise error_class(parsed_response, operation_name)\nbotocore.exceptions.ClientError: An error occurred (RequestLimitExceeded) when calling the DescribeSnapshotAttribute operation (reached max retries: 4): Request limit exceeded.\n"
    },
    {
        "additional_details": null,
        "exception": "Failed to describe EC2 snapshot attributes: An error occurred (RequestLimitExceeded) when calling the DescribeSnapshotAttribute operation (reached max retries: 4): Request limit exceeded.",
        "file": "ec2.py",
        "line": 121,
        "traceback": "Traceback (most recent call last):\n  File \"c:\\Go\\ScoutSuite\\ScoutSuite\\providers\\aws\\facade\\ec2.py\", line 121, in _get_and_set_snapshot_attributes\n    snapshot['CreateVolumePermissions'] = await run_concurrently(lambda: ec2_client.describe_snapshot_attribute(\n  File \"C:\\Python37\\lib\\concurrent\\futures\\thread.py\", line 57, in run\n    result = self.fn(*self.args, **self.kwargs)\n  File \"c:\\Go\\ScoutSuite\\ScoutSuite\\providers\\aws\\facade\\ec2.py\", line 123, in <lambda>\n    SnapshotId=snapshot['SnapshotId'])['CreateVolumePermissions'])\n  File \"C:\\Python37\\lib\\site-packages\\botocore\\client.py\", line 357, in _api_call\n    return self._make_api_call(operation_name, kwargs)\n  File \"C:\\Python37\\lib\\site-packages\\botocore\\client.py\", line 661, in _make_api_call\n    raise error_class(parsed_response, operation_name)\nbotocore.exceptions.ClientError: An error occurred (RequestLimitExceeded) when calling the DescribeSnapshotAttribute operation (reached max retries: 4): Request limit exceeded.\n"
    },
    {
        "additional_details": null,
        "exception": "Failed to describe EC2 snapshot attributes: An error occurred (RequestLimitExceeded) when calling the DescribeSnapshotAttribute operation (reached max retries: 4): Request limit exceeded.",
        "file": "ec2.py",
        "line": 121,
        "traceback": "Traceback (most recent call last):\n  File \"c:\\Go\\ScoutSuite\\ScoutSuite\\providers\\aws\\facade\\ec2.py\", line 121, in _get_and_set_snapshot_attributes\n    snapshot['CreateVolumePermissions'] = await run_concurrently(lambda: ec2_client.describe_snapshot_attribute(\n  File \"C:\\Python37\\lib\\concurrent\\futures\\thread.py\", line 57, in run\n    result = self.fn(*self.args, **self.kwargs)\n  File \"c:\\Go\\ScoutSuite\\ScoutSuite\\providers\\aws\\facade\\ec2.py\", line 123, in <lambda>\n    SnapshotId=snapshot['SnapshotId'])['CreateVolumePermissions'])\n  File \"C:\\Python37\\lib\\site-packages\\botocore\\client.py\", line 357, in _api_call\n    return self._make_api_call(operation_name, kwargs)\n  File \"C:\\Python37\\lib\\site-packages\\botocore\\client.py\", line 661, in _make_api_call\n    raise error_class(parsed_response, operation_name)\nbotocore.exceptions.ClientError: An error occurred (RequestLimitExceeded) when calling the DescribeSnapshotAttribute operation (reached max retries: 4): Request limit exceeded.\n"
    },
    {
        "additional_details": null,
        "exception": "Failed to describe EC2 snapshot attributes: An error occurred (RequestLimitExceeded) when calling the DescribeSnapshotAttribute operation (reached max retries: 4): Request limit exceeded.",
        "file": "ec2.py",
        "line": 121,
        "traceback": "Traceback (most recent call last):\n  File \"c:\\Go\\ScoutSuite\\ScoutSuite\\providers\\aws\\facade\\ec2.py\", line 121, in _get_and_set_snapshot_attributes\n    snapshot['CreateVolumePermissions'] = await run_concurrently(lambda: ec2_client.describe_snapshot_attribute(\n  File \"C:\\Python37\\lib\\concurrent\\futures\\thread.py\", line 57, in run\n    result = self.fn(*self.args, **self.kwargs)\n  File \"c:\\Go\\ScoutSuite\\ScoutSuite\\providers\\aws\\facade\\ec2.py\", line 123, in <lambda>\n    SnapshotId=snapshot['SnapshotId'])['CreateVolumePermissions'])\n  File \"C:\\Python37\\lib\\site-packages\\botocore\\client.py\", line 357, in _api_call\n    return self._make_api_call(operation_name, kwargs)\n  File \"C:\\Python37\\lib\\site-packages\\botocore\\client.py\", line 661, in _make_api_call\n    raise error_class(parsed_response, operation_name)\nbotocore.exceptions.ClientError: An error occurred (RequestLimitExceeded) when calling the DescribeSnapshotAttribute operation (reached max retries: 4): Request limit exceeded.\n"
    },
    {
        "additional_details": null,
        "exception": "Failed to describe EC2 snapshot attributes: An error occurred (RequestLimitExceeded) when calling the DescribeSnapshotAttribute operation (reached max retries: 4): Request limit exceeded.",
        "file": "ec2.py",
        "line": 121,
        "traceback": "Traceback (most recent call last):\n  File \"c:\\Go\\ScoutSuite\\ScoutSuite\\providers\\aws\\facade\\ec2.py\", line 121, in _get_and_set_snapshot_attributes\n    snapshot['CreateVolumePermissions'] = await run_concurrently(lambda: ec2_client.describe_snapshot_attribute(\n  File \"C:\\Python37\\lib\\concurrent\\futures\\thread.py\", line 57, in run\n    result = self.fn(*self.args, **self.kwargs)\n  File \"c:\\Go\\ScoutSuite\\ScoutSuite\\providers\\aws\\facade\\ec2.py\", line 123, in <lambda>\n    SnapshotId=snapshot['SnapshotId'])['CreateVolumePermissions'])\n  File \"C:\\Python37\\lib\\site-packages\\botocore\\client.py\", line 357, in _api_call\n    return self._make_api_call(operation_name, kwargs)\n  File \"C:\\Python37\\lib\\site-packages\\botocore\\client.py\", line 661, in _make_api_call\n    raise error_class(parsed_response, operation_name)\nbotocore.exceptions.ClientError: An error occurred (RequestLimitExceeded) when calling the DescribeSnapshotAttribute operation (reached max retries: 4): Request limit exceeded.\n"
    },
    {
        "additional_details": null,
        "exception": "Failed to describe EC2 snapshot attributes: An error occurred (RequestLimitExceeded) when calling the DescribeSnapshotAttribute operation (reached max retries: 4): Request limit exceeded.",
        "file": "ec2.py",
        "line": 121,
        "traceback": "Traceback (most recent call last):\n  File \"c:\\Go\\ScoutSuite\\ScoutSuite\\providers\\aws\\facade\\ec2.py\", line 121, in _get_and_set_snapshot_attributes\n    snapshot['CreateVolumePermissions'] = await run_concurrently(lambda: ec2_client.describe_snapshot_attribute(\n  File \"C:\\Python37\\lib\\concurrent\\futures\\thread.py\", line 57, in run\n    result = self.fn(*self.args, **self.kwargs)\n  File \"c:\\Go\\ScoutSuite\\ScoutSuite\\providers\\aws\\facade\\ec2.py\", line 123, in <lambda>\n    SnapshotId=snapshot['SnapshotId'])['CreateVolumePermissions'])\n  File \"C:\\Python37\\lib\\site-packages\\botocore\\client.py\", line 357, in _api_call\n    return self._make_api_call(operation_name, kwargs)\n  File \"C:\\Python37\\lib\\site-packages\\botocore\\client.py\", line 661, in _make_api_call\n    raise error_class(parsed_response, operation_name)\nbotocore.exceptions.ClientError: An error occurred (RequestLimitExceeded) when calling the DescribeSnapshotAttribute operation (reached max retries: 4): Request limit exceeded.\n"
    },
    {
        "additional_details": null,
        "exception": "Failed to describe EC2 snapshot attributes: An error occurred (RequestLimitExceeded) when calling the DescribeSnapshotAttribute operation (reached max retries: 4): Request limit exceeded.",
        "file": "ec2.py",
        "line": 121,
        "traceback": "Traceback (most recent call last):\n  File \"c:\\Go\\ScoutSuite\\ScoutSuite\\providers\\aws\\facade\\ec2.py\", line 121, in _get_and_set_snapshot_attributes\n    snapshot['CreateVolumePermissions'] = await run_concurrently(lambda: ec2_client.describe_snapshot_attribute(\n  File \"C:\\Python37\\lib\\concurrent\\futures\\thread.py\", line 57, in run\n    result = self.fn(*self.args, **self.kwargs)\n  File \"c:\\Go\\ScoutSuite\\ScoutSuite\\providers\\aws\\facade\\ec2.py\", line 123, in <lambda>\n    SnapshotId=snapshot['SnapshotId'])['CreateVolumePermissions'])\n  File \"C:\\Python37\\lib\\site-packages\\botocore\\client.py\", line 357, in _api_call\n    return self._make_api_call(operation_name, kwargs)\n  File \"C:\\Python37\\lib\\site-packages\\botocore\\client.py\", line 661, in _make_api_call\n    raise error_class(parsed_response, operation_name)\nbotocore.exceptions.ClientError: An error occurred (RequestLimitExceeded) when calling the DescribeSnapshotAttribute operation (reached max retries: 4): Request limit exceeded.\n"
    },
    {
        "additional_details": null,
        "exception": "Failed to describe EC2 snapshot attributes: An error occurred (RequestLimitExceeded) when calling the DescribeSnapshotAttribute operation (reached max retries: 4): Request limit exceeded.",
        "file": "ec2.py",
        "line": 121,
        "traceback": "Traceback (most recent call last):\n  File \"c:\\Go\\ScoutSuite\\ScoutSuite\\providers\\aws\\facade\\ec2.py\", line 121, in _get_and_set_snapshot_attributes\n    snapshot['CreateVolumePermissions'] = await run_concurrently(lambda: ec2_client.describe_snapshot_attribute(\n  File \"C:\\Python37\\lib\\concurrent\\futures\\thread.py\", line 57, in run\n    result = self.fn(*self.args, **self.kwargs)\n  File \"c:\\Go\\ScoutSuite\\ScoutSuite\\providers\\aws\\facade\\ec2.py\", line 123, in <lambda>\n    SnapshotId=snapshot['SnapshotId'])['CreateVolumePermissions'])\n  File \"C:\\Python37\\lib\\site-packages\\botocore\\client.py\", line 357, in _api_call\n    return self._make_api_call(operation_name, kwargs)\n  File \"C:\\Python37\\lib\\site-packages\\botocore\\client.py\", line 661, in _make_api_call\n    raise error_class(parsed_response, operation_name)\nbotocore.exceptions.ClientError: An error occurred (RequestLimitExceeded) when calling the DescribeSnapshotAttribute operation (reached max retries: 4): Request limit exceeded.\n"
    },
    {
        "additional_details": null,
        "exception": "Failed to describe EC2 snapshot attributes: An error occurred (RequestLimitExceeded) when calling the DescribeSnapshotAttribute operation (reached max retries: 4): Request limit exceeded.",
        "file": "ec2.py",
        "line": 121,
        "traceback": "Traceback (most recent call last):\n  File \"c:\\Go\\ScoutSuite\\ScoutSuite\\providers\\aws\\facade\\ec2.py\", line 121, in _get_and_set_snapshot_attributes\n    snapshot['CreateVolumePermissions'] = await run_concurrently(lambda: ec2_client.describe_snapshot_attribute(\n  File \"C:\\Python37\\lib\\concurrent\\futures\\thread.py\", line 57, in run\n    result = self.fn(*self.args, **self.kwargs)\n  File \"c:\\Go\\ScoutSuite\\ScoutSuite\\providers\\aws\\facade\\ec2.py\", line 123, in <lambda>\n    SnapshotId=snapshot['SnapshotId'])['CreateVolumePermissions'])\n  File \"C:\\Python37\\lib\\site-packages\\botocore\\client.py\", line 357, in _api_call\n    return self._make_api_call(operation_name, kwargs)\n  File \"C:\\Python37\\lib\\site-packages\\botocore\\client.py\", line 661, in _make_api_call\n    raise error_class(parsed_response, operation_name)\nbotocore.exceptions.ClientError: An error occurred (RequestLimitExceeded) when calling the DescribeSnapshotAttribute operation (reached max retries: 4): Request limit exceeded.\n"
    },
    {
        "additional_details": null,
        "exception": "Failed to describe EC2 snapshot attributes: An error occurred (RequestLimitExceeded) when calling the DescribeSnapshotAttribute operation (reached max retries: 4): Request limit exceeded.",
        "file": "ec2.py",
        "line": 121,
        "traceback": "Traceback (most recent call last):\n  File \"c:\\Go\\ScoutSuite\\ScoutSuite\\providers\\aws\\facade\\ec2.py\", line 121, in _get_and_set_snapshot_attributes\n    snapshot['CreateVolumePermissions'] = await run_concurrently(lambda: ec2_client.describe_snapshot_attribute(\n  File \"C:\\Python37\\lib\\concurrent\\futures\\thread.py\", line 57, in run\n    result = self.fn(*self.args, **self.kwargs)\n  File \"c:\\Go\\ScoutSuite\\ScoutSuite\\providers\\aws\\facade\\ec2.py\", line 123, in <lambda>\n    SnapshotId=snapshot['SnapshotId'])['CreateVolumePermissions'])\n  File \"C:\\Python37\\lib\\site-packages\\botocore\\client.py\", line 357, in _api_call\n    return self._make_api_call(operation_name, kwargs)\n  File \"C:\\Python37\\lib\\site-packages\\botocore\\client.py\", line 661, in _make_api_call\n    raise error_class(parsed_response, operation_name)\nbotocore.exceptions.ClientError: An error occurred (RequestLimitExceeded) when calling the DescribeSnapshotAttribute operation (reached max retries: 4): Request limit exceeded.\n"
    },
    {
        "additional_details": null,
        "exception": "Failed to describe EC2 snapshot attributes: An error occurred (RequestLimitExceeded) when calling the DescribeSnapshotAttribute operation (reached max retries: 4): Request limit exceeded.",
        "file": "ec2.py",
        "line": 121,
        "traceback": "Traceback (most recent call last):\n  File \"c:\\Go\\ScoutSuite\\ScoutSuite\\providers\\aws\\facade\\ec2.py\", line 121, in _get_and_set_snapshot_attributes\n    snapshot['CreateVolumePermissions'] = await run_concurrently(lambda: ec2_client.describe_snapshot_attribute(\n  File \"C:\\Python37\\lib\\concurrent\\futures\\thread.py\", line 57, in run\n    result = self.fn(*self.args, **self.kwargs)\n  File \"c:\\Go\\ScoutSuite\\ScoutSuite\\providers\\aws\\facade\\ec2.py\", line 123, in <lambda>\n    SnapshotId=snapshot['SnapshotId'])['CreateVolumePermissions'])\n  File \"C:\\Python37\\lib\\site-packages\\botocore\\client.py\", line 357, in _api_call\n    return self._make_api_call(operation_name, kwargs)\n  File \"C:\\Python37\\lib\\site-packages\\botocore\\client.py\", line 661, in _make_api_call\n    raise error_class(parsed_response, operation_name)\nbotocore.exceptions.ClientError: An error occurred (RequestLimitExceeded) when calling the DescribeSnapshotAttribute operation (reached max retries: 4): Request limit exceeded.\n"
    },
    {
        "additional_details": null,
        "exception": "Failed to describe EC2 snapshot attributes: An error occurred (RequestLimitExceeded) when calling the DescribeSnapshotAttribute operation (reached max retries: 4): Request limit exceeded.",
        "file": "ec2.py",
        "line": 121,
        "traceback": "Traceback (most recent call last):\n  File \"c:\\Go\\ScoutSuite\\ScoutSuite\\providers\\aws\\facade\\ec2.py\", line 121, in _get_and_set_snapshot_attributes\n    snapshot['CreateVolumePermissions'] = await run_concurrently(lambda: ec2_client.describe_snapshot_attribute(\n  File \"C:\\Python37\\lib\\concurrent\\futures\\thread.py\", line 57, in run\n    result = self.fn(*self.args, **self.kwargs)\n  File \"c:\\Go\\ScoutSuite\\ScoutSuite\\providers\\aws\\facade\\ec2.py\", line 123, in <lambda>\n    SnapshotId=snapshot['SnapshotId'])['CreateVolumePermissions'])\n  File \"C:\\Python37\\lib\\site-packages\\botocore\\client.py\", line 357, in _api_call\n    return self._make_api_call(operation_name, kwargs)\n  File \"C:\\Python37\\lib\\site-packages\\botocore\\client.py\", line 661, in _make_api_call\n    raise error_class(parsed_response, operation_name)\nbotocore.exceptions.ClientError: An error occurred (RequestLimitExceeded) when calling the DescribeSnapshotAttribute operation (reached max retries: 4): Request limit exceeded.\n"
    },
    {
        "additional_details": null,
        "exception": "Failed to describe EC2 snapshot attributes: An error occurred (RequestLimitExceeded) when calling the DescribeSnapshotAttribute operation (reached max retries: 4): Request limit exceeded.",
        "file": "ec2.py",
        "line": 121,
        "traceback": "Traceback (most recent call last):\n  File \"c:\\Go\\ScoutSuite\\ScoutSuite\\providers\\aws\\facade\\ec2.py\", line 121, in _get_and_set_snapshot_attributes\n    snapshot['CreateVolumePermissions'] = await run_concurrently(lambda: ec2_client.describe_snapshot_attribute(\n  File \"C:\\Python37\\lib\\concurrent\\futures\\thread.py\", line 57, in run\n    result = self.fn(*self.args, **self.kwargs)\n  File \"c:\\Go\\ScoutSuite\\ScoutSuite\\providers\\aws\\facade\\ec2.py\", line 123, in <lambda>\n    SnapshotId=snapshot['SnapshotId'])['CreateVolumePermissions'])\n  File \"C:\\Python37\\lib\\site-packages\\botocore\\client.py\", line 357, in _api_call\n    return self._make_api_call(operation_name, kwargs)\n  File \"C:\\Python37\\lib\\site-packages\\botocore\\client.py\", line 661, in _make_api_call\n    raise error_class(parsed_response, operation_name)\nbotocore.exceptions.ClientError: An error occurred (RequestLimitExceeded) when calling the DescribeSnapshotAttribute operation (reached max retries: 4): Request limit exceeded.\n"
    },
    {
        "additional_details": null,
        "exception": "Failed to describe EC2 snapshot attributes: An error occurred (RequestLimitExceeded) when calling the DescribeSnapshotAttribute operation (reached max retries: 4): Request limit exceeded.",
        "file": "ec2.py",
        "line": 121,
        "traceback": "Traceback (most recent call last):\n  File \"c:\\Go\\ScoutSuite\\ScoutSuite\\providers\\aws\\facade\\ec2.py\", line 121, in _get_and_set_snapshot_attributes\n    snapshot['CreateVolumePermissions'] = await run_concurrently(lambda: ec2_client.describe_snapshot_attribute(\n  File \"C:\\Python37\\lib\\concurrent\\futures\\thread.py\", line 57, in run\n    result = self.fn(*self.args, **self.kwargs)\n  File \"c:\\Go\\ScoutSuite\\ScoutSuite\\providers\\aws\\facade\\ec2.py\", line 123, in <lambda>\n    SnapshotId=snapshot['SnapshotId'])['CreateVolumePermissions'])\n  File \"C:\\Python37\\lib\\site-packages\\botocore\\client.py\", line 357, in _api_call\n    return self._make_api_call(operation_name, kwargs)\n  File \"C:\\Python37\\lib\\site-packages\\botocore\\client.py\", line 661, in _make_api_call\n    raise error_class(parsed_response, operation_name)\nbotocore.exceptions.ClientError: An error occurred (RequestLimitExceeded) when calling the DescribeSnapshotAttribute operation (reached max retries: 4): Request limit exceeded.\n"
    },
    {
        "additional_details": null,
        "exception": "Failed to describe EC2 snapshot attributes: An error occurred (RequestLimitExceeded) when calling the DescribeSnapshotAttribute operation (reached max retries: 4): Request limit exceeded.",
        "file": "ec2.py",
        "line": 121,
        "traceback": "Traceback (most recent call last):\n  File \"c:\\Go\\ScoutSuite\\ScoutSuite\\providers\\aws\\facade\\ec2.py\", line 121, in _get_and_set_snapshot_attributes\n    snapshot['CreateVolumePermissions'] = await run_concurrently(lambda: ec2_client.describe_snapshot_attribute(\n  File \"C:\\Python37\\lib\\concurrent\\futures\\thread.py\", line 57, in run\n    result = self.fn(*self.args, **self.kwargs)\n  File \"c:\\Go\\ScoutSuite\\ScoutSuite\\providers\\aws\\facade\\ec2.py\", line 123, in <lambda>\n    SnapshotId=snapshot['SnapshotId'])['CreateVolumePermissions'])\n  File \"C:\\Python37\\lib\\site-packages\\botocore\\client.py\", line 357, in _api_call\n    return self._make_api_call(operation_name, kwargs)\n  File \"C:\\Python37\\lib\\site-packages\\botocore\\client.py\", line 661, in _make_api_call\n    raise error_class(parsed_response, operation_name)\nbotocore.exceptions.ClientError: An error occurred (RequestLimitExceeded) when calling the DescribeSnapshotAttribute operation (reached max retries: 4): Request limit exceeded.\n"
    },
    {
        "additional_details": null,
        "exception": "Failed to describe EC2 snapshot attributes: An error occurred (RequestLimitExceeded) when calling the DescribeSnapshotAttribute operation (reached max retries: 4): Request limit exceeded.",
        "file": "ec2.py",
        "line": 121,
        "traceback": "Traceback (most recent call last):\n  File \"c:\\Go\\ScoutSuite\\ScoutSuite\\providers\\aws\\facade\\ec2.py\", line 121, in _get_and_set_snapshot_attributes\n    snapshot['CreateVolumePermissions'] = await run_concurrently(lambda: ec2_client.describe_snapshot_attribute(\n  File \"C:\\Python37\\lib\\concurrent\\futures\\thread.py\", line 57, in run\n    result = self.fn(*self.args, **self.kwargs)\n  File \"c:\\Go\\ScoutSuite\\ScoutSuite\\providers\\aws\\facade\\ec2.py\", line 123, in <lambda>\n    SnapshotId=snapshot['SnapshotId'])['CreateVolumePermissions'])\n  File \"C:\\Python37\\lib\\site-packages\\botocore\\client.py\", line 357, in _api_call\n    return self._make_api_call(operation_name, kwargs)\n  File \"C:\\Python37\\lib\\site-packages\\botocore\\client.py\", line 661, in _make_api_call\n    raise error_class(parsed_response, operation_name)\nbotocore.exceptions.ClientError: An error occurred (RequestLimitExceeded) when calling the DescribeSnapshotAttribute operation (reached max retries: 4): Request limit exceeded.\n"
    },
    {
        "additional_details": null,
        "exception": "Failed to describe EC2 snapshot attributes: An error occurred (RequestLimitExceeded) when calling the DescribeSnapshotAttribute operation (reached max retries: 4): Request limit exceeded.",
        "file": "ec2.py",
        "line": 121,
        "traceback": "Traceback (most recent call last):\n  File \"c:\\Go\\ScoutSuite\\ScoutSuite\\providers\\aws\\facade\\ec2.py\", line 121, in _get_and_set_snapshot_attributes\n    snapshot['CreateVolumePermissions'] = await run_concurrently(lambda: ec2_client.describe_snapshot_attribute(\n  File \"C:\\Python37\\lib\\concurrent\\futures\\thread.py\", line 57, in run\n    result = self.fn(*self.args, **self.kwargs)\n  File \"c:\\Go\\ScoutSuite\\ScoutSuite\\providers\\aws\\facade\\ec2.py\", line 123, in <lambda>\n    SnapshotId=snapshot['SnapshotId'])['CreateVolumePermissions'])\n  File \"C:\\Python37\\lib\\site-packages\\botocore\\client.py\", line 357, in _api_call\n    return self._make_api_call(operation_name, kwargs)\n  File \"C:\\Python37\\lib\\site-packages\\botocore\\client.py\", line 661, in _make_api_call\n    raise error_class(parsed_response, operation_name)\nbotocore.exceptions.ClientError: An error occurred (RequestLimitExceeded) when calling the DescribeSnapshotAttribute operation (reached max retries: 4): Request limit exceeded.\n"
    },
    {
        "additional_details": null,
        "exception": "Failed to describe EC2 snapshot attributes: An error occurred (RequestLimitExceeded) when calling the DescribeSnapshotAttribute operation (reached max retries: 4): Request limit exceeded.",
        "file": "ec2.py",
        "line": 121,
        "traceback": "Traceback (most recent call last):\n  File \"c:\\Go\\ScoutSuite\\ScoutSuite\\providers\\aws\\facade\\ec2.py\", line 121, in _get_and_set_snapshot_attributes\n    snapshot['CreateVolumePermissions'] = await run_concurrently(lambda: ec2_client.describe_snapshot_attribute(\n  File \"C:\\Python37\\lib\\concurrent\\futures\\thread.py\", line 57, in run\n    result = self.fn(*self.args, **self.kwargs)\n  File \"c:\\Go\\ScoutSuite\\ScoutSuite\\providers\\aws\\facade\\ec2.py\", line 123, in <lambda>\n    SnapshotId=snapshot['SnapshotId'])['CreateVolumePermissions'])\n  File \"C:\\Python37\\lib\\site-packages\\botocore\\client.py\", line 357, in _api_call\n    return self._make_api_call(operation_name, kwargs)\n  File \"C:\\Python37\\lib\\site-packages\\botocore\\client.py\", line 661, in _make_api_call\n    raise error_class(parsed_response, operation_name)\nbotocore.exceptions.ClientError: An error occurred (RequestLimitExceeded) when calling the DescribeSnapshotAttribute operation (reached max retries: 4): Request limit exceeded.\n"
    },
    {
        "additional_details": null,
        "exception": "Failed to describe EC2 snapshot attributes: An error occurred (RequestLimitExceeded) when calling the DescribeSnapshotAttribute operation (reached max retries: 4): Request limit exceeded.",
        "file": "ec2.py",
        "line": 121,
        "traceback": "Traceback (most recent call last):\n  File \"c:\\Go\\ScoutSuite\\ScoutSuite\\providers\\aws\\facade\\ec2.py\", line 121, in _get_and_set_snapshot_attributes\n    snapshot['CreateVolumePermissions'] = await run_concurrently(lambda: ec2_client.describe_snapshot_attribute(\n  File \"C:\\Python37\\lib\\concurrent\\futures\\thread.py\", line 57, in run\n    result = self.fn(*self.args, **self.kwargs)\n  File \"c:\\Go\\ScoutSuite\\ScoutSuite\\providers\\aws\\facade\\ec2.py\", line 123, in <lambda>\n    SnapshotId=snapshot['SnapshotId'])['CreateVolumePermissions'])\n  File \"C:\\Python37\\lib\\site-packages\\botocore\\client.py\", line 357, in _api_call\n    return self._make_api_call(operation_name, kwargs)\n  File \"C:\\Python37\\lib\\site-packages\\botocore\\client.py\", line 661, in _make_api_call\n    raise error_class(parsed_response, operation_name)\nbotocore.exceptions.ClientError: An error occurred (RequestLimitExceeded) when calling the DescribeSnapshotAttribute operation (reached max retries: 4): Request limit exceeded.\n"
    },
    {
        "additional_details": null,
        "exception": "Failed to describe EC2 snapshot attributes: An error occurred (RequestLimitExceeded) when calling the DescribeSnapshotAttribute operation (reached max retries: 4): Request limit exceeded.",
        "file": "ec2.py",
        "line": 121,
        "traceback": "Traceback (most recent call last):\n  File \"c:\\Go\\ScoutSuite\\ScoutSuite\\providers\\aws\\facade\\ec2.py\", line 121, in _get_and_set_snapshot_attributes\n    snapshot['CreateVolumePermissions'] = await run_concurrently(lambda: ec2_client.describe_snapshot_attribute(\n  File \"C:\\Python37\\lib\\concurrent\\futures\\thread.py\", line 57, in run\n    result = self.fn(*self.args, **self.kwargs)\n  File \"c:\\Go\\ScoutSuite\\ScoutSuite\\providers\\aws\\facade\\ec2.py\", line 123, in <lambda>\n    SnapshotId=snapshot['SnapshotId'])['CreateVolumePermissions'])\n  File \"C:\\Python37\\lib\\site-packages\\botocore\\client.py\", line 357, in _api_call\n    return self._make_api_call(operation_name, kwargs)\n  File \"C:\\Python37\\lib\\site-packages\\botocore\\client.py\", line 661, in _make_api_call\n    raise error_class(parsed_response, operation_name)\nbotocore.exceptions.ClientError: An error occurred (RequestLimitExceeded) when calling the DescribeSnapshotAttribute operation (reached max retries: 4): Request limit exceeded.\n"
    },
    {
        "additional_details": null,
        "exception": "Failed to describe EC2 snapshot attributes: An error occurred (RequestLimitExceeded) when calling the DescribeSnapshotAttribute operation (reached max retries: 4): Request limit exceeded.",
        "file": "ec2.py",
        "line": 121,
        "traceback": "Traceback (most recent call last):\n  File \"c:\\Go\\ScoutSuite\\ScoutSuite\\providers\\aws\\facade\\ec2.py\", line 121, in _get_and_set_snapshot_attributes\n    snapshot['CreateVolumePermissions'] = await run_concurrently(lambda: ec2_client.describe_snapshot_attribute(\n  File \"C:\\Python37\\lib\\concurrent\\futures\\thread.py\", line 57, in run\n    result = self.fn(*self.args, **self.kwargs)\n  File \"c:\\Go\\ScoutSuite\\ScoutSuite\\providers\\aws\\facade\\ec2.py\", line 123, in <lambda>\n    SnapshotId=snapshot['SnapshotId'])['CreateVolumePermissions'])\n  File \"C:\\Python37\\lib\\site-packages\\botocore\\client.py\", line 357, in _api_call\n    return self._make_api_call(operation_name, kwargs)\n  File \"C:\\Python37\\lib\\site-packages\\botocore\\client.py\", line 661, in _make_api_call\n    raise error_class(parsed_response, operation_name)\nbotocore.exceptions.ClientError: An error occurred (RequestLimitExceeded) when calling the DescribeSnapshotAttribute operation (reached max retries: 4): Request limit exceeded.\n"
    },
    {
        "additional_details": null,
        "exception": "Failed to describe EC2 snapshot attributes: An error occurred (RequestLimitExceeded) when calling the DescribeSnapshotAttribute operation (reached max retries: 4): Request limit exceeded.",
        "file": "ec2.py",
        "line": 121,
        "traceback": "Traceback (most recent call last):\n  File \"c:\\Go\\ScoutSuite\\ScoutSuite\\providers\\aws\\facade\\ec2.py\", line 121, in _get_and_set_snapshot_attributes\n    snapshot['CreateVolumePermissions'] = await run_concurrently(lambda: ec2_client.describe_snapshot_attribute(\n  File \"C:\\Python37\\lib\\concurrent\\futures\\thread.py\", line 57, in run\n    result = self.fn(*self.args, **self.kwargs)\n  File \"c:\\Go\\ScoutSuite\\ScoutSuite\\providers\\aws\\facade\\ec2.py\", line 123, in <lambda>\n    SnapshotId=snapshot['SnapshotId'])['CreateVolumePermissions'])\n  File \"C:\\Python37\\lib\\site-packages\\botocore\\client.py\", line 357, in _api_call\n    return self._make_api_call(operation_name, kwargs)\n  File \"C:\\Python37\\lib\\site-packages\\botocore\\client.py\", line 661, in _make_api_call\n    raise error_class(parsed_response, operation_name)\nbotocore.exceptions.ClientError: An error occurred (RequestLimitExceeded) when calling the DescribeSnapshotAttribute operation (reached max retries: 4): Request limit exceeded.\n"
    },
    {
        "additional_details": null,
        "exception": "Failed to describe EC2 snapshot attributes: An error occurred (RequestLimitExceeded) when calling the DescribeSnapshotAttribute operation (reached max retries: 4): Request limit exceeded.",
        "file": "ec2.py",
        "line": 121,
        "traceback": "Traceback (most recent call last):\n  File \"c:\\Go\\ScoutSuite\\ScoutSuite\\providers\\aws\\facade\\ec2.py\", line 121, in _get_and_set_snapshot_attributes\n    snapshot['CreateVolumePermissions'] = await run_concurrently(lambda: ec2_client.describe_snapshot_attribute(\n  File \"C:\\Python37\\lib\\concurrent\\futures\\thread.py\", line 57, in run\n    result = self.fn(*self.args, **self.kwargs)\n  File \"c:\\Go\\ScoutSuite\\ScoutSuite\\providers\\aws\\facade\\ec2.py\", line 123, in <lambda>\n    SnapshotId=snapshot['SnapshotId'])['CreateVolumePermissions'])\n  File \"C:\\Python37\\lib\\site-packages\\botocore\\client.py\", line 357, in _api_call\n    return self._make_api_call(operation_name, kwargs)\n  File \"C:\\Python37\\lib\\site-packages\\botocore\\client.py\", line 661, in _make_api_call\n    raise error_class(parsed_response, operation_name)\nbotocore.exceptions.ClientError: An error occurred (RequestLimitExceeded) when calling the DescribeSnapshotAttribute operation (reached max retries: 4): Request limit exceeded.\n"
    },
    {
        "additional_details": null,
        "exception": "Failed to describe EC2 snapshot attributes: An error occurred (RequestLimitExceeded) when calling the DescribeSnapshotAttribute operation (reached max retries: 4): Request limit exceeded.",
        "file": "ec2.py",
        "line": 121,
        "traceback": "Traceback (most recent call last):\n  File \"c:\\Go\\ScoutSuite\\ScoutSuite\\providers\\aws\\facade\\ec2.py\", line 121, in _get_and_set_snapshot_attributes\n    snapshot['CreateVolumePermissions'] = await run_concurrently(lambda: ec2_client.describe_snapshot_attribute(\n  File \"C:\\Python37\\lib\\concurrent\\futures\\thread.py\", line 57, in run\n    result = self.fn(*self.args, **self.kwargs)\n  File \"c:\\Go\\ScoutSuite\\ScoutSuite\\providers\\aws\\facade\\ec2.py\", line 123, in <lambda>\n    SnapshotId=snapshot['SnapshotId'])['CreateVolumePermissions'])\n  File \"C:\\Python37\\lib\\site-packages\\botocore\\client.py\", line 357, in _api_call\n    return self._make_api_call(operation_name, kwargs)\n  File \"C:\\Python37\\lib\\site-packages\\botocore\\client.py\", line 661, in _make_api_call\n    raise error_class(parsed_response, operation_name)\nbotocore.exceptions.ClientError: An error occurred (RequestLimitExceeded) when calling the DescribeSnapshotAttribute operation (reached max retries: 4): Request limit exceeded.\n"
    },
    {
        "additional_details": null,
        "exception": "Failed to describe EC2 snapshot attributes: An error occurred (RequestLimitExceeded) when calling the DescribeSnapshotAttribute operation (reached max retries: 4): Request limit exceeded.",
        "file": "ec2.py",
        "line": 121,
        "traceback": "Traceback (most recent call last):\n  File \"c:\\Go\\ScoutSuite\\ScoutSuite\\providers\\aws\\facade\\ec2.py\", line 121, in _get_and_set_snapshot_attributes\n    snapshot['CreateVolumePermissions'] = await run_concurrently(lambda: ec2_client.describe_snapshot_attribute(\n  File \"C:\\Python37\\lib\\concurrent\\futures\\thread.py\", line 57, in run\n    result = self.fn(*self.args, **self.kwargs)\n  File \"c:\\Go\\ScoutSuite\\ScoutSuite\\providers\\aws\\facade\\ec2.py\", line 123, in <lambda>\n    SnapshotId=snapshot['SnapshotId'])['CreateVolumePermissions'])\n  File \"C:\\Python37\\lib\\site-packages\\botocore\\client.py\", line 357, in _api_call\n    return self._make_api_call(operation_name, kwargs)\n  File \"C:\\Python37\\lib\\site-packages\\botocore\\client.py\", line 661, in _make_api_call\n    raise error_class(parsed_response, operation_name)\nbotocore.exceptions.ClientError: An error occurred (RequestLimitExceeded) when calling the DescribeSnapshotAttribute operation (reached max retries: 4): Request limit exceeded.\n"
    },
    {
        "additional_details": null,
        "exception": "Failed to describe EC2 snapshot attributes: An error occurred (RequestLimitExceeded) when calling the DescribeSnapshotAttribute operation (reached max retries: 4): Request limit exceeded.",
        "file": "ec2.py",
        "line": 121,
        "traceback": "Traceback (most recent call last):\n  File \"c:\\Go\\ScoutSuite\\ScoutSuite\\providers\\aws\\facade\\ec2.py\", line 121, in _get_and_set_snapshot_attributes\n    snapshot['CreateVolumePermissions'] = await run_concurrently(lambda: ec2_client.describe_snapshot_attribute(\n  File \"C:\\Python37\\lib\\concurrent\\futures\\thread.py\", line 57, in run\n    result = self.fn(*self.args, **self.kwargs)\n  File \"c:\\Go\\ScoutSuite\\ScoutSuite\\providers\\aws\\facade\\ec2.py\", line 123, in <lambda>\n    SnapshotId=snapshot['SnapshotId'])['CreateVolumePermissions'])\n  File \"C:\\Python37\\lib\\site-packages\\botocore\\client.py\", line 357, in _api_call\n    return self._make_api_call(operation_name, kwargs)\n  File \"C:\\Python37\\lib\\site-packages\\botocore\\client.py\", line 661, in _make_api_call\n    raise error_class(parsed_response, operation_name)\nbotocore.exceptions.ClientError: An error occurred (RequestLimitExceeded) when calling the DescribeSnapshotAttribute operation (reached max retries: 4): Request limit exceeded.\n"
    },
    {
        "additional_details": null,
        "exception": "Failed to describe EC2 snapshot attributes: An error occurred (RequestLimitExceeded) when calling the DescribeSnapshotAttribute operation (reached max retries: 4): Request limit exceeded.",
        "file": "ec2.py",
        "line": 121,
        "traceback": "Traceback (most recent call last):\n  File \"c:\\Go\\ScoutSuite\\ScoutSuite\\providers\\aws\\facade\\ec2.py\", line 121, in _get_and_set_snapshot_attributes\n    snapshot['CreateVolumePermissions'] = await run_concurrently(lambda: ec2_client.describe_snapshot_attribute(\n  File \"C:\\Python37\\lib\\concurrent\\futures\\thread.py\", line 57, in run\n    result = self.fn(*self.args, **self.kwargs)\n  File \"c:\\Go\\ScoutSuite\\ScoutSuite\\providers\\aws\\facade\\ec2.py\", line 123, in <lambda>\n    SnapshotId=snapshot['SnapshotId'])['CreateVolumePermissions'])\n  File \"C:\\Python37\\lib\\site-packages\\botocore\\client.py\", line 357, in _api_call\n    return self._make_api_call(operation_name, kwargs)\n  File \"C:\\Python37\\lib\\site-packages\\botocore\\client.py\", line 661, in _make_api_call\n    raise error_class(parsed_response, operation_name)\nbotocore.exceptions.ClientError: An error occurred (RequestLimitExceeded) when calling the DescribeSnapshotAttribute operation (reached max retries: 4): Request limit exceeded.\n"
    },
    {
        "additional_details": null,
        "exception": "Failed to describe EC2 snapshot attributes: An error occurred (RequestLimitExceeded) when calling the DescribeSnapshotAttribute operation (reached max retries: 4): Request limit exceeded.",
        "file": "ec2.py",
        "line": 121,
        "traceback": "Traceback (most recent call last):\n  File \"c:\\Go\\ScoutSuite\\ScoutSuite\\providers\\aws\\facade\\ec2.py\", line 121, in _get_and_set_snapshot_attributes\n    snapshot['CreateVolumePermissions'] = await run_concurrently(lambda: ec2_client.describe_snapshot_attribute(\n  File \"C:\\Python37\\lib\\concurrent\\futures\\thread.py\", line 57, in run\n    result = self.fn(*self.args, **self.kwargs)\n  File \"c:\\Go\\ScoutSuite\\ScoutSuite\\providers\\aws\\facade\\ec2.py\", line 123, in <lambda>\n    SnapshotId=snapshot['SnapshotId'])['CreateVolumePermissions'])\n  File \"C:\\Python37\\lib\\site-packages\\botocore\\client.py\", line 357, in _api_call\n    return self._make_api_call(operation_name, kwargs)\n  File \"C:\\Python37\\lib\\site-packages\\botocore\\client.py\", line 661, in _make_api_call\n    raise error_class(parsed_response, operation_name)\nbotocore.exceptions.ClientError: An error occurred (RequestLimitExceeded) when calling the DescribeSnapshotAttribute operation (reached max retries: 4): Request limit exceeded.\n"
    },
    {
        "additional_details": null,
        "exception": "Failed to describe EC2 snapshot attributes: An error occurred (RequestLimitExceeded) when calling the DescribeSnapshotAttribute operation (reached max retries: 4): Request limit exceeded.",
        "file": "ec2.py",
        "line": 121,
        "traceback": "Traceback (most recent call last):\n  File \"c:\\Go\\ScoutSuite\\ScoutSuite\\providers\\aws\\facade\\ec2.py\", line 121, in _get_and_set_snapshot_attributes\n    snapshot['CreateVolumePermissions'] = await run_concurrently(lambda: ec2_client.describe_snapshot_attribute(\n  File \"C:\\Python37\\lib\\concurrent\\futures\\thread.py\", line 57, in run\n    result = self.fn(*self.args, **self.kwargs)\n  File \"c:\\Go\\ScoutSuite\\ScoutSuite\\providers\\aws\\facade\\ec2.py\", line 123, in <lambda>\n    SnapshotId=snapshot['SnapshotId'])['CreateVolumePermissions'])\n  File \"C:\\Python37\\lib\\site-packages\\botocore\\client.py\", line 357, in _api_call\n    return self._make_api_call(operation_name, kwargs)\n  File \"C:\\Python37\\lib\\site-packages\\botocore\\client.py\", line 661, in _make_api_call\n    raise error_class(parsed_response, operation_name)\nbotocore.exceptions.ClientError: An error occurred (RequestLimitExceeded) when calling the DescribeSnapshotAttribute operation (reached max retries: 4): Request limit exceeded.\n"
    },
    {
        "additional_details": null,
        "exception": "Failed to describe EC2 snapshot attributes: An error occurred (RequestLimitExceeded) when calling the DescribeSnapshotAttribute operation (reached max retries: 4): Request limit exceeded.",
        "file": "ec2.py",
        "line": 121,
        "traceback": "Traceback (most recent call last):\n  File \"c:\\Go\\ScoutSuite\\ScoutSuite\\providers\\aws\\facade\\ec2.py\", line 121, in _get_and_set_snapshot_attributes\n    snapshot['CreateVolumePermissions'] = await run_concurrently(lambda: ec2_client.describe_snapshot_attribute(\n  File \"C:\\Python37\\lib\\concurrent\\futures\\thread.py\", line 57, in run\n    result = self.fn(*self.args, **self.kwargs)\n  File \"c:\\Go\\ScoutSuite\\ScoutSuite\\providers\\aws\\facade\\ec2.py\", line 123, in <lambda>\n    SnapshotId=snapshot['SnapshotId'])['CreateVolumePermissions'])\n  File \"C:\\Python37\\lib\\site-packages\\botocore\\client.py\", line 357, in _api_call\n    return self._make_api_call(operation_name, kwargs)\n  File \"C:\\Python37\\lib\\site-packages\\botocore\\client.py\", line 661, in _make_api_call\n    raise error_class(parsed_response, operation_name)\nbotocore.exceptions.ClientError: An error occurred (RequestLimitExceeded) when calling the DescribeSnapshotAttribute operation (reached max retries: 4): Request limit exceeded.\n"
    },
    {
        "additional_details": null,
        "exception": "Failed to describe EC2 snapshot attributes: An error occurred (RequestLimitExceeded) when calling the DescribeSnapshotAttribute operation (reached max retries: 4): Request limit exceeded.",
        "file": "ec2.py",
        "line": 121,
        "traceback": "Traceback (most recent call last):\n  File \"c:\\Go\\ScoutSuite\\ScoutSuite\\providers\\aws\\facade\\ec2.py\", line 121, in _get_and_set_snapshot_attributes\n    snapshot['CreateVolumePermissions'] = await run_concurrently(lambda: ec2_client.describe_snapshot_attribute(\n  File \"C:\\Python37\\lib\\concurrent\\futures\\thread.py\", line 57, in run\n    result = self.fn(*self.args, **self.kwargs)\n  File \"c:\\Go\\ScoutSuite\\ScoutSuite\\providers\\aws\\facade\\ec2.py\", line 123, in <lambda>\n    SnapshotId=snapshot['SnapshotId'])['CreateVolumePermissions'])\n  File \"C:\\Python37\\lib\\site-packages\\botocore\\client.py\", line 357, in _api_call\n    return self._make_api_call(operation_name, kwargs)\n  File \"C:\\Python37\\lib\\site-packages\\botocore\\client.py\", line 661, in _make_api_call\n    raise error_class(parsed_response, operation_name)\nbotocore.exceptions.ClientError: An error occurred (RequestLimitExceeded) when calling the DescribeSnapshotAttribute operation (reached max retries: 4): Request limit exceeded.\n"
    },
    {
        "additional_details": null,
        "exception": "Failed to describe EC2 snapshot attributes: An error occurred (RequestLimitExceeded) when calling the DescribeSnapshotAttribute operation (reached max retries: 4): Request limit exceeded.",
        "file": "ec2.py",
        "line": 121,
        "traceback": "Traceback (most recent call last):\n  File \"c:\\Go\\ScoutSuite\\ScoutSuite\\providers\\aws\\facade\\ec2.py\", line 121, in _get_and_set_snapshot_attributes\n    snapshot['CreateVolumePermissions'] = await run_concurrently(lambda: ec2_client.describe_snapshot_attribute(\n  File \"C:\\Python37\\lib\\concurrent\\futures\\thread.py\", line 57, in run\n    result = self.fn(*self.args, **self.kwargs)\n  File \"c:\\Go\\ScoutSuite\\ScoutSuite\\providers\\aws\\facade\\ec2.py\", line 123, in <lambda>\n    SnapshotId=snapshot['SnapshotId'])['CreateVolumePermissions'])\n  File \"C:\\Python37\\lib\\site-packages\\botocore\\client.py\", line 357, in _api_call\n    return self._make_api_call(operation_name, kwargs)\n  File \"C:\\Python37\\lib\\site-packages\\botocore\\client.py\", line 661, in _make_api_call\n    raise error_class(parsed_response, operation_name)\nbotocore.exceptions.ClientError: An error occurred (RequestLimitExceeded) when calling the DescribeSnapshotAttribute operation (reached max retries: 4): Request limit exceeded.\n"
    },
    {
        "additional_details": null,
        "exception": "Failed to describe EC2 snapshot attributes: An error occurred (RequestLimitExceeded) when calling the DescribeSnapshotAttribute operation (reached max retries: 4): Request limit exceeded.",
        "file": "ec2.py",
        "line": 121,
        "traceback": "Traceback (most recent call last):\n  File \"c:\\Go\\ScoutSuite\\ScoutSuite\\providers\\aws\\facade\\ec2.py\", line 121, in _get_and_set_snapshot_attributes\n    snapshot['CreateVolumePermissions'] = await run_concurrently(lambda: ec2_client.describe_snapshot_attribute(\n  File \"C:\\Python37\\lib\\concurrent\\futures\\thread.py\", line 57, in run\n    result = self.fn(*self.args, **self.kwargs)\n  File \"c:\\Go\\ScoutSuite\\ScoutSuite\\providers\\aws\\facade\\ec2.py\", line 123, in <lambda>\n    SnapshotId=snapshot['SnapshotId'])['CreateVolumePermissions'])\n  File \"C:\\Python37\\lib\\site-packages\\botocore\\client.py\", line 357, in _api_call\n    return self._make_api_call(operation_name, kwargs)\n  File \"C:\\Python37\\lib\\site-packages\\botocore\\client.py\", line 661, in _make_api_call\n    raise error_class(parsed_response, operation_name)\nbotocore.exceptions.ClientError: An error occurred (RequestLimitExceeded) when calling the DescribeSnapshotAttribute operation (reached max retries: 4): Request limit exceeded.\n"
    },
    {
        "additional_details": null,
        "exception": "Failed to describe EC2 snapshot attributes: An error occurred (RequestLimitExceeded) when calling the DescribeSnapshotAttribute operation (reached max retries: 4): Request limit exceeded.",
        "file": "ec2.py",
        "line": 121,
        "traceback": "Traceback (most recent call last):\n  File \"c:\\Go\\ScoutSuite\\ScoutSuite\\providers\\aws\\facade\\ec2.py\", line 121, in _get_and_set_snapshot_attributes\n    snapshot['CreateVolumePermissions'] = await run_concurrently(lambda: ec2_client.describe_snapshot_attribute(\n  File \"C:\\Python37\\lib\\concurrent\\futures\\thread.py\", line 57, in run\n    result = self.fn(*self.args, **self.kwargs)\n  File \"c:\\Go\\ScoutSuite\\ScoutSuite\\providers\\aws\\facade\\ec2.py\", line 123, in <lambda>\n    SnapshotId=snapshot['SnapshotId'])['CreateVolumePermissions'])\n  File \"C:\\Python37\\lib\\site-packages\\botocore\\client.py\", line 357, in _api_call\n    return self._make_api_call(operation_name, kwargs)\n  File \"C:\\Python37\\lib\\site-packages\\botocore\\client.py\", line 661, in _make_api_call\n    raise error_class(parsed_response, operation_name)\nbotocore.exceptions.ClientError: An error occurred (RequestLimitExceeded) when calling the DescribeSnapshotAttribute operation (reached max retries: 4): Request limit exceeded.\n"
    },
    {
        "additional_details": null,
        "exception": "Failed to describe EC2 snapshot attributes: An error occurred (RequestLimitExceeded) when calling the DescribeSnapshotAttribute operation (reached max retries: 4): Request limit exceeded.",
        "file": "ec2.py",
        "line": 121,
        "traceback": "Traceback (most recent call last):\n  File \"c:\\Go\\ScoutSuite\\ScoutSuite\\providers\\aws\\facade\\ec2.py\", line 121, in _get_and_set_snapshot_attributes\n    snapshot['CreateVolumePermissions'] = await run_concurrently(lambda: ec2_client.describe_snapshot_attribute(\n  File \"C:\\Python37\\lib\\concurrent\\futures\\thread.py\", line 57, in run\n    result = self.fn(*self.args, **self.kwargs)\n  File \"c:\\Go\\ScoutSuite\\ScoutSuite\\providers\\aws\\facade\\ec2.py\", line 123, in <lambda>\n    SnapshotId=snapshot['SnapshotId'])['CreateVolumePermissions'])\n  File \"C:\\Python37\\lib\\site-packages\\botocore\\client.py\", line 357, in _api_call\n    return self._make_api_call(operation_name, kwargs)\n  File \"C:\\Python37\\lib\\site-packages\\botocore\\client.py\", line 661, in _make_api_call\n    raise error_class(parsed_response, operation_name)\nbotocore.exceptions.ClientError: An error occurred (RequestLimitExceeded) when calling the DescribeSnapshotAttribute operation (reached max retries: 4): Request limit exceeded.\n"
    },
    {
        "additional_details": null,
        "exception": "Failed to describe EC2 snapshot attributes: An error occurred (RequestLimitExceeded) when calling the DescribeSnapshotAttribute operation (reached max retries: 4): Request limit exceeded.",
        "file": "ec2.py",
        "line": 121,
        "traceback": "Traceback (most recent call last):\n  File \"c:\\Go\\ScoutSuite\\ScoutSuite\\providers\\aws\\facade\\ec2.py\", line 121, in _get_and_set_snapshot_attributes\n    snapshot['CreateVolumePermissions'] = await run_concurrently(lambda: ec2_client.describe_snapshot_attribute(\n  File \"C:\\Python37\\lib\\concurrent\\futures\\thread.py\", line 57, in run\n    result = self.fn(*self.args, **self.kwargs)\n  File \"c:\\Go\\ScoutSuite\\ScoutSuite\\providers\\aws\\facade\\ec2.py\", line 123, in <lambda>\n    SnapshotId=snapshot['SnapshotId'])['CreateVolumePermissions'])\n  File \"C:\\Python37\\lib\\site-packages\\botocore\\client.py\", line 357, in _api_call\n    return self._make_api_call(operation_name, kwargs)\n  File \"C:\\Python37\\lib\\site-packages\\botocore\\client.py\", line 661, in _make_api_call\n    raise error_class(parsed_response, operation_name)\nbotocore.exceptions.ClientError: An error occurred (RequestLimitExceeded) when calling the DescribeSnapshotAttribute operation (reached max retries: 4): Request limit exceeded.\n"
    },
    {
        "additional_details": null,
        "exception": "Failed to describe EC2 snapshot attributes: An error occurred (RequestLimitExceeded) when calling the DescribeSnapshotAttribute operation (reached max retries: 4): Request limit exceeded.",
        "file": "ec2.py",
        "line": 121,
        "traceback": "Traceback (most recent call last):\n  File \"c:\\Go\\ScoutSuite\\ScoutSuite\\providers\\aws\\facade\\ec2.py\", line 121, in _get_and_set_snapshot_attributes\n    snapshot['CreateVolumePermissions'] = await run_concurrently(lambda: ec2_client.describe_snapshot_attribute(\n  File \"C:\\Python37\\lib\\concurrent\\futures\\thread.py\", line 57, in run\n    result = self.fn(*self.args, **self.kwargs)\n  File \"c:\\Go\\ScoutSuite\\ScoutSuite\\providers\\aws\\facade\\ec2.py\", line 123, in <lambda>\n    SnapshotId=snapshot['SnapshotId'])['CreateVolumePermissions'])\n  File \"C:\\Python37\\lib\\site-packages\\botocore\\client.py\", line 357, in _api_call\n    return self._make_api_call(operation_name, kwargs)\n  File \"C:\\Python37\\lib\\site-packages\\botocore\\client.py\", line 661, in _make_api_call\n    raise error_class(parsed_response, operation_name)\nbotocore.exceptions.ClientError: An error occurred (RequestLimitExceeded) when calling the DescribeSnapshotAttribute operation (reached max retries: 4): Request limit exceeded.\n"
    },
    {
        "additional_details": null,
        "exception": "Failed to describe EC2 snapshot attributes: An error occurred (RequestLimitExceeded) when calling the DescribeSnapshotAttribute operation (reached max retries: 4): Request limit exceeded.",
        "file": "ec2.py",
        "line": 121,
        "traceback": "Traceback (most recent call last):\n  File \"c:\\Go\\ScoutSuite\\ScoutSuite\\providers\\aws\\facade\\ec2.py\", line 121, in _get_and_set_snapshot_attributes\n    snapshot['CreateVolumePermissions'] = await run_concurrently(lambda: ec2_client.describe_snapshot_attribute(\n  File \"C:\\Python37\\lib\\concurrent\\futures\\thread.py\", line 57, in run\n    result = self.fn(*self.args, **self.kwargs)\n  File \"c:\\Go\\ScoutSuite\\ScoutSuite\\providers\\aws\\facade\\ec2.py\", line 123, in <lambda>\n    SnapshotId=snapshot['SnapshotId'])['CreateVolumePermissions'])\n  File \"C:\\Python37\\lib\\site-packages\\botocore\\client.py\", line 357, in _api_call\n    return self._make_api_call(operation_name, kwargs)\n  File \"C:\\Python37\\lib\\site-packages\\botocore\\client.py\", line 661, in _make_api_call\n    raise error_class(parsed_response, operation_name)\nbotocore.exceptions.ClientError: An error occurred (RequestLimitExceeded) when calling the DescribeSnapshotAttribute operation (reached max retries: 4): Request limit exceeded.\n"
    },
    {
        "additional_details": null,
        "exception": "Failed to describe EC2 snapshot attributes: An error occurred (RequestLimitExceeded) when calling the DescribeSnapshotAttribute operation (reached max retries: 4): Request limit exceeded.",
        "file": "ec2.py",
        "line": 121,
        "traceback": "Traceback (most recent call last):\n  File \"c:\\Go\\ScoutSuite\\ScoutSuite\\providers\\aws\\facade\\ec2.py\", line 121, in _get_and_set_snapshot_attributes\n    snapshot['CreateVolumePermissions'] = await run_concurrently(lambda: ec2_client.describe_snapshot_attribute(\n  File \"C:\\Python37\\lib\\concurrent\\futures\\thread.py\", line 57, in run\n    result = self.fn(*self.args, **self.kwargs)\n  File \"c:\\Go\\ScoutSuite\\ScoutSuite\\providers\\aws\\facade\\ec2.py\", line 123, in <lambda>\n    SnapshotId=snapshot['SnapshotId'])['CreateVolumePermissions'])\n  File \"C:\\Python37\\lib\\site-packages\\botocore\\client.py\", line 357, in _api_call\n    return self._make_api_call(operation_name, kwargs)\n  File \"C:\\Python37\\lib\\site-packages\\botocore\\client.py\", line 661, in _make_api_call\n    raise error_class(parsed_response, operation_name)\nbotocore.exceptions.ClientError: An error occurred (RequestLimitExceeded) when calling the DescribeSnapshotAttribute operation (reached max retries: 4): Request limit exceeded.\n"
    },
    {
        "additional_details": null,
        "exception": "Failed to describe EC2 snapshot attributes: An error occurred (RequestLimitExceeded) when calling the DescribeSnapshotAttribute operation (reached max retries: 4): Request limit exceeded.",
        "file": "ec2.py",
        "line": 121,
        "traceback": "Traceback (most recent call last):\n  File \"c:\\Go\\ScoutSuite\\ScoutSuite\\providers\\aws\\facade\\ec2.py\", line 121, in _get_and_set_snapshot_attributes\n    snapshot['CreateVolumePermissions'] = await run_concurrently(lambda: ec2_client.describe_snapshot_attribute(\n  File \"C:\\Python37\\lib\\concurrent\\futures\\thread.py\", line 57, in run\n    result = self.fn(*self.args, **self.kwargs)\n  File \"c:\\Go\\ScoutSuite\\ScoutSuite\\providers\\aws\\facade\\ec2.py\", line 123, in <lambda>\n    SnapshotId=snapshot['SnapshotId'])['CreateVolumePermissions'])\n  File \"C:\\Python37\\lib\\site-packages\\botocore\\client.py\", line 357, in _api_call\n    return self._make_api_call(operation_name, kwargs)\n  File \"C:\\Python37\\lib\\site-packages\\botocore\\client.py\", line 661, in _make_api_call\n    raise error_class(parsed_response, operation_name)\nbotocore.exceptions.ClientError: An error occurred (RequestLimitExceeded) when calling the DescribeSnapshotAttribute operation (reached max retries: 4): Request limit exceeded.\n"
    },
    {
        "additional_details": null,
        "exception": "Failed to describe EC2 snapshot attributes: An error occurred (RequestLimitExceeded) when calling the DescribeSnapshotAttribute operation (reached max retries: 4): Request limit exceeded.",
        "file": "ec2.py",
        "line": 121,
        "traceback": "Traceback (most recent call last):\n  File \"c:\\Go\\ScoutSuite\\ScoutSuite\\providers\\aws\\facade\\ec2.py\", line 121, in _get_and_set_snapshot_attributes\n    snapshot['CreateVolumePermissions'] = await run_concurrently(lambda: ec2_client.describe_snapshot_attribute(\n  File \"C:\\Python37\\lib\\concurrent\\futures\\thread.py\", line 57, in run\n    result = self.fn(*self.args, **self.kwargs)\n  File \"c:\\Go\\ScoutSuite\\ScoutSuite\\providers\\aws\\facade\\ec2.py\", line 123, in <lambda>\n    SnapshotId=snapshot['SnapshotId'])['CreateVolumePermissions'])\n  File \"C:\\Python37\\lib\\site-packages\\botocore\\client.py\", line 357, in _api_call\n    return self._make_api_call(operation_name, kwargs)\n  File \"C:\\Python37\\lib\\site-packages\\botocore\\client.py\", line 661, in _make_api_call\n    raise error_class(parsed_response, operation_name)\nbotocore.exceptions.ClientError: An error occurred (RequestLimitExceeded) when calling the DescribeSnapshotAttribute operation (reached max retries: 4): Request limit exceeded.\n"
    },
    {
        "additional_details": null,
        "exception": "Failed to describe EC2 snapshot attributes: An error occurred (RequestLimitExceeded) when calling the DescribeSnapshotAttribute operation (reached max retries: 4): Request limit exceeded.",
        "file": "ec2.py",
        "line": 121,
        "traceback": "Traceback (most recent call last):\n  File \"c:\\Go\\ScoutSuite\\ScoutSuite\\providers\\aws\\facade\\ec2.py\", line 121, in _get_and_set_snapshot_attributes\n    snapshot['CreateVolumePermissions'] = await run_concurrently(lambda: ec2_client.describe_snapshot_attribute(\n  File \"C:\\Python37\\lib\\concurrent\\futures\\thread.py\", line 57, in run\n    result = self.fn(*self.args, **self.kwargs)\n  File \"c:\\Go\\ScoutSuite\\ScoutSuite\\providers\\aws\\facade\\ec2.py\", line 123, in <lambda>\n    SnapshotId=snapshot['SnapshotId'])['CreateVolumePermissions'])\n  File \"C:\\Python37\\lib\\site-packages\\botocore\\client.py\", line 357, in _api_call\n    return self._make_api_call(operation_name, kwargs)\n  File \"C:\\Python37\\lib\\site-packages\\botocore\\client.py\", line 661, in _make_api_call\n    raise error_class(parsed_response, operation_name)\nbotocore.exceptions.ClientError: An error occurred (RequestLimitExceeded) when calling the DescribeSnapshotAttribute operation (reached max retries: 4): Request limit exceeded.\n"
    },
    {
        "additional_details": null,
        "exception": "Failed to describe EC2 snapshot attributes: An error occurred (RequestLimitExceeded) when calling the DescribeSnapshotAttribute operation (reached max retries: 4): Request limit exceeded.",
        "file": "ec2.py",
        "line": 121,
        "traceback": "Traceback (most recent call last):\n  File \"c:\\Go\\ScoutSuite\\ScoutSuite\\providers\\aws\\facade\\ec2.py\", line 121, in _get_and_set_snapshot_attributes\n    snapshot['CreateVolumePermissions'] = await run_concurrently(lambda: ec2_client.describe_snapshot_attribute(\n  File \"C:\\Python37\\lib\\concurrent\\futures\\thread.py\", line 57, in run\n    result = self.fn(*self.args, **self.kwargs)\n  File \"c:\\Go\\ScoutSuite\\ScoutSuite\\providers\\aws\\facade\\ec2.py\", line 123, in <lambda>\n    SnapshotId=snapshot['SnapshotId'])['CreateVolumePermissions'])\n  File \"C:\\Python37\\lib\\site-packages\\botocore\\client.py\", line 357, in _api_call\n    return self._make_api_call(operation_name, kwargs)\n  File \"C:\\Python37\\lib\\site-packages\\botocore\\client.py\", line 661, in _make_api_call\n    raise error_class(parsed_response, operation_name)\nbotocore.exceptions.ClientError: An error occurred (RequestLimitExceeded) when calling the DescribeSnapshotAttribute operation (reached max retries: 4): Request limit exceeded.\n"
    },
    {
        "additional_details": null,
        "exception": "Failed to describe EC2 snapshot attributes: An error occurred (RequestLimitExceeded) when calling the DescribeSnapshotAttribute operation (reached max retries: 4): Request limit exceeded.",
        "file": "ec2.py",
        "line": 121,
        "traceback": "Traceback (most recent call last):\n  File \"c:\\Go\\ScoutSuite\\ScoutSuite\\providers\\aws\\facade\\ec2.py\", line 121, in _get_and_set_snapshot_attributes\n    snapshot['CreateVolumePermissions'] = await run_concurrently(lambda: ec2_client.describe_snapshot_attribute(\n  File \"C:\\Python37\\lib\\concurrent\\futures\\thread.py\", line 57, in run\n    result = self.fn(*self.args, **self.kwargs)\n  File \"c:\\Go\\ScoutSuite\\ScoutSuite\\providers\\aws\\facade\\ec2.py\", line 123, in <lambda>\n    SnapshotId=snapshot['SnapshotId'])['CreateVolumePermissions'])\n  File \"C:\\Python37\\lib\\site-packages\\botocore\\client.py\", line 357, in _api_call\n    return self._make_api_call(operation_name, kwargs)\n  File \"C:\\Python37\\lib\\site-packages\\botocore\\client.py\", line 661, in _make_api_call\n    raise error_class(parsed_response, operation_name)\nbotocore.exceptions.ClientError: An error occurred (RequestLimitExceeded) when calling the DescribeSnapshotAttribute operation (reached max retries: 4): Request limit exceeded.\n"
    },
    {
        "additional_details": null,
        "exception": "Failed to describe EC2 snapshot attributes: An error occurred (RequestLimitExceeded) when calling the DescribeSnapshotAttribute operation (reached max retries: 4): Request limit exceeded.",
        "file": "ec2.py",
        "line": 121,
        "traceback": "Traceback (most recent call last):\n  File \"c:\\Go\\ScoutSuite\\ScoutSuite\\providers\\aws\\facade\\ec2.py\", line 121, in _get_and_set_snapshot_attributes\n    snapshot['CreateVolumePermissions'] = await run_concurrently(lambda: ec2_client.describe_snapshot_attribute(\n  File \"C:\\Python37\\lib\\concurrent\\futures\\thread.py\", line 57, in run\n    result = self.fn(*self.args, **self.kwargs)\n  File \"c:\\Go\\ScoutSuite\\ScoutSuite\\providers\\aws\\facade\\ec2.py\", line 123, in <lambda>\n    SnapshotId=snapshot['SnapshotId'])['CreateVolumePermissions'])\n  File \"C:\\Python37\\lib\\site-packages\\botocore\\client.py\", line 357, in _api_call\n    return self._make_api_call(operation_name, kwargs)\n  File \"C:\\Python37\\lib\\site-packages\\botocore\\client.py\", line 661, in _make_api_call\n    raise error_class(parsed_response, operation_name)\nbotocore.exceptions.ClientError: An error occurred (RequestLimitExceeded) when calling the DescribeSnapshotAttribute operation (reached max retries: 4): Request limit exceeded.\n"
    },
    {
        "additional_details": null,
        "exception": "Failed to describe EC2 snapshot attributes: An error occurred (RequestLimitExceeded) when calling the DescribeSnapshotAttribute operation (reached max retries: 4): Request limit exceeded.",
        "file": "ec2.py",
        "line": 121,
        "traceback": "Traceback (most recent call last):\n  File \"c:\\Go\\ScoutSuite\\ScoutSuite\\providers\\aws\\facade\\ec2.py\", line 121, in _get_and_set_snapshot_attributes\n    snapshot['CreateVolumePermissions'] = await run_concurrently(lambda: ec2_client.describe_snapshot_attribute(\n  File \"C:\\Python37\\lib\\concurrent\\futures\\thread.py\", line 57, in run\n    result = self.fn(*self.args, **self.kwargs)\n  File \"c:\\Go\\ScoutSuite\\ScoutSuite\\providers\\aws\\facade\\ec2.py\", line 123, in <lambda>\n    SnapshotId=snapshot['SnapshotId'])['CreateVolumePermissions'])\n  File \"C:\\Python37\\lib\\site-packages\\botocore\\client.py\", line 357, in _api_call\n    return self._make_api_call(operation_name, kwargs)\n  File \"C:\\Python37\\lib\\site-packages\\botocore\\client.py\", line 661, in _make_api_call\n    raise error_class(parsed_response, operation_name)\nbotocore.exceptions.ClientError: An error occurred (RequestLimitExceeded) when calling the DescribeSnapshotAttribute operation (reached max retries: 4): Request limit exceeded.\n"
    },
    {
        "additional_details": null,
        "exception": "Failed to describe EC2 snapshot attributes: An error occurred (RequestLimitExceeded) when calling the DescribeSnapshotAttribute operation (reached max retries: 4): Request limit exceeded.",
        "file": "ec2.py",
        "line": 121,
        "traceback": "Traceback (most recent call last):\n  File \"c:\\Go\\ScoutSuite\\ScoutSuite\\providers\\aws\\facade\\ec2.py\", line 121, in _get_and_set_snapshot_attributes\n    snapshot['CreateVolumePermissions'] = await run_concurrently(lambda: ec2_client.describe_snapshot_attribute(\n  File \"C:\\Python37\\lib\\concurrent\\futures\\thread.py\", line 57, in run\n    result = self.fn(*self.args, **self.kwargs)\n  File \"c:\\Go\\ScoutSuite\\ScoutSuite\\providers\\aws\\facade\\ec2.py\", line 123, in <lambda>\n    SnapshotId=snapshot['SnapshotId'])['CreateVolumePermissions'])\n  File \"C:\\Python37\\lib\\site-packages\\botocore\\client.py\", line 357, in _api_call\n    return self._make_api_call(operation_name, kwargs)\n  File \"C:\\Python37\\lib\\site-packages\\botocore\\client.py\", line 661, in _make_api_call\n    raise error_class(parsed_response, operation_name)\nbotocore.exceptions.ClientError: An error occurred (RequestLimitExceeded) when calling the DescribeSnapshotAttribute operation (reached max retries: 4): Request limit exceeded.\n"
    },
    {
        "additional_details": null,
        "exception": "Failed to describe EC2 snapshot attributes: An error occurred (RequestLimitExceeded) when calling the DescribeSnapshotAttribute operation (reached max retries: 4): Request limit exceeded.",
        "file": "ec2.py",
        "line": 121,
        "traceback": "Traceback (most recent call last):\n  File \"c:\\Go\\ScoutSuite\\ScoutSuite\\providers\\aws\\facade\\ec2.py\", line 121, in _get_and_set_snapshot_attributes\n    snapshot['CreateVolumePermissions'] = await run_concurrently(lambda: ec2_client.describe_snapshot_attribute(\n  File \"C:\\Python37\\lib\\concurrent\\futures\\thread.py\", line 57, in run\n    result = self.fn(*self.args, **self.kwargs)\n  File \"c:\\Go\\ScoutSuite\\ScoutSuite\\providers\\aws\\facade\\ec2.py\", line 123, in <lambda>\n    SnapshotId=snapshot['SnapshotId'])['CreateVolumePermissions'])\n  File \"C:\\Python37\\lib\\site-packages\\botocore\\client.py\", line 357, in _api_call\n    return self._make_api_call(operation_name, kwargs)\n  File \"C:\\Python37\\lib\\site-packages\\botocore\\client.py\", line 661, in _make_api_call\n    raise error_class(parsed_response, operation_name)\nbotocore.exceptions.ClientError: An error occurred (RequestLimitExceeded) when calling the DescribeSnapshotAttribute operation (reached max retries: 4): Request limit exceeded.\n"
    },
    {
        "additional_details": null,
        "exception": "Failed to describe EC2 snapshot attributes: An error occurred (RequestLimitExceeded) when calling the DescribeSnapshotAttribute operation (reached max retries: 4): Request limit exceeded.",
        "file": "ec2.py",
        "line": 121,
        "traceback": "Traceback (most recent call last):\n  File \"c:\\Go\\ScoutSuite\\ScoutSuite\\providers\\aws\\facade\\ec2.py\", line 121, in _get_and_set_snapshot_attributes\n    snapshot['CreateVolumePermissions'] = await run_concurrently(lambda: ec2_client.describe_snapshot_attribute(\n  File \"C:\\Python37\\lib\\concurrent\\futures\\thread.py\", line 57, in run\n    result = self.fn(*self.args, **self.kwargs)\n  File \"c:\\Go\\ScoutSuite\\ScoutSuite\\providers\\aws\\facade\\ec2.py\", line 123, in <lambda>\n    SnapshotId=snapshot['SnapshotId'])['CreateVolumePermissions'])\n  File \"C:\\Python37\\lib\\site-packages\\botocore\\client.py\", line 357, in _api_call\n    return self._make_api_call(operation_name, kwargs)\n  File \"C:\\Python37\\lib\\site-packages\\botocore\\client.py\", line 661, in _make_api_call\n    raise error_class(parsed_response, operation_name)\nbotocore.exceptions.ClientError: An error occurred (RequestLimitExceeded) when calling the DescribeSnapshotAttribute operation (reached max retries: 4): Request limit exceeded.\n"
    },
    {
        "additional_details": null,
        "exception": "Failed to describe EC2 snapshot attributes: An error occurred (RequestLimitExceeded) when calling the DescribeSnapshotAttribute operation (reached max retries: 4): Request limit exceeded.",
        "file": "ec2.py",
        "line": 121,
        "traceback": "Traceback (most recent call last):\n  File \"c:\\Go\\ScoutSuite\\ScoutSuite\\providers\\aws\\facade\\ec2.py\", line 121, in _get_and_set_snapshot_attributes\n    snapshot['CreateVolumePermissions'] = await run_concurrently(lambda: ec2_client.describe_snapshot_attribute(\n  File \"C:\\Python37\\lib\\concurrent\\futures\\thread.py\", line 57, in run\n    result = self.fn(*self.args, **self.kwargs)\n  File \"c:\\Go\\ScoutSuite\\ScoutSuite\\providers\\aws\\facade\\ec2.py\", line 123, in <lambda>\n    SnapshotId=snapshot['SnapshotId'])['CreateVolumePermissions'])\n  File \"C:\\Python37\\lib\\site-packages\\botocore\\client.py\", line 357, in _api_call\n    return self._make_api_call(operation_name, kwargs)\n  File \"C:\\Python37\\lib\\site-packages\\botocore\\client.py\", line 661, in _make_api_call\n    raise error_class(parsed_response, operation_name)\nbotocore.exceptions.ClientError: An error occurred (RequestLimitExceeded) when calling the DescribeSnapshotAttribute operation (reached max retries: 4): Request limit exceeded.\n"
    },
    {
        "additional_details": null,
        "exception": "Failed to describe EC2 snapshot attributes: An error occurred (RequestLimitExceeded) when calling the DescribeSnapshotAttribute operation (reached max retries: 4): Request limit exceeded.",
        "file": "ec2.py",
        "line": 121,
        "traceback": "Traceback (most recent call last):\n  File \"c:\\Go\\ScoutSuite\\ScoutSuite\\providers\\aws\\facade\\ec2.py\", line 121, in _get_and_set_snapshot_attributes\n    snapshot['CreateVolumePermissions'] = await run_concurrently(lambda: ec2_client.describe_snapshot_attribute(\n  File \"C:\\Python37\\lib\\concurrent\\futures\\thread.py\", line 57, in run\n    result = self.fn(*self.args, **self.kwargs)\n  File \"c:\\Go\\ScoutSuite\\ScoutSuite\\providers\\aws\\facade\\ec2.py\", line 123, in <lambda>\n    SnapshotId=snapshot['SnapshotId'])['CreateVolumePermissions'])\n  File \"C:\\Python37\\lib\\site-packages\\botocore\\client.py\", line 357, in _api_call\n    return self._make_api_call(operation_name, kwargs)\n  File \"C:\\Python37\\lib\\site-packages\\botocore\\client.py\", line 661, in _make_api_call\n    raise error_class(parsed_response, operation_name)\nbotocore.exceptions.ClientError: An error occurred (RequestLimitExceeded) when calling the DescribeSnapshotAttribute operation (reached max retries: 4): Request limit exceeded.\n"
    },
    {
        "additional_details": null,
        "exception": "Failed to describe EC2 snapshot attributes: An error occurred (RequestLimitExceeded) when calling the DescribeSnapshotAttribute operation (reached max retries: 4): Request limit exceeded.",
        "file": "ec2.py",
        "line": 121,
        "traceback": "Traceback (most recent call last):\n  File \"c:\\Go\\ScoutSuite\\ScoutSuite\\providers\\aws\\facade\\ec2.py\", line 121, in _get_and_set_snapshot_attributes\n    snapshot['CreateVolumePermissions'] = await run_concurrently(lambda: ec2_client.describe_snapshot_attribute(\n  File \"C:\\Python37\\lib\\concurrent\\futures\\thread.py\", line 57, in run\n    result = self.fn(*self.args, **self.kwargs)\n  File \"c:\\Go\\ScoutSuite\\ScoutSuite\\providers\\aws\\facade\\ec2.py\", line 123, in <lambda>\n    SnapshotId=snapshot['SnapshotId'])['CreateVolumePermissions'])\n  File \"C:\\Python37\\lib\\site-packages\\botocore\\client.py\", line 357, in _api_call\n    return self._make_api_call(operation_name, kwargs)\n  File \"C:\\Python37\\lib\\site-packages\\botocore\\client.py\", line 661, in _make_api_call\n    raise error_class(parsed_response, operation_name)\nbotocore.exceptions.ClientError: An error occurred (RequestLimitExceeded) when calling the DescribeSnapshotAttribute operation (reached max retries: 4): Request limit exceeded.\n"
    },
    {
        "additional_details": null,
        "exception": "Failed to describe EC2 snapshot attributes: An error occurred (RequestLimitExceeded) when calling the DescribeSnapshotAttribute operation (reached max retries: 4): Request limit exceeded.",
        "file": "ec2.py",
        "line": 121,
        "traceback": "Traceback (most recent call last):\n  File \"c:\\Go\\ScoutSuite\\ScoutSuite\\providers\\aws\\facade\\ec2.py\", line 121, in _get_and_set_snapshot_attributes\n    snapshot['CreateVolumePermissions'] = await run_concurrently(lambda: ec2_client.describe_snapshot_attribute(\n  File \"C:\\Python37\\lib\\concurrent\\futures\\thread.py\", line 57, in run\n    result = self.fn(*self.args, **self.kwargs)\n  File \"c:\\Go\\ScoutSuite\\ScoutSuite\\providers\\aws\\facade\\ec2.py\", line 123, in <lambda>\n    SnapshotId=snapshot['SnapshotId'])['CreateVolumePermissions'])\n  File \"C:\\Python37\\lib\\site-packages\\botocore\\client.py\", line 357, in _api_call\n    return self._make_api_call(operation_name, kwargs)\n  File \"C:\\Python37\\lib\\site-packages\\botocore\\client.py\", line 661, in _make_api_call\n    raise error_class(parsed_response, operation_name)\nbotocore.exceptions.ClientError: An error occurred (RequestLimitExceeded) when calling the DescribeSnapshotAttribute operation (reached max retries: 4): Request limit exceeded.\n"
    },
    {
        "additional_details": null,
        "exception": "Failed to describe EC2 snapshot attributes: An error occurred (RequestLimitExceeded) when calling the DescribeSnapshotAttribute operation (reached max retries: 4): Request limit exceeded.",
        "file": "ec2.py",
        "line": 121,
        "traceback": "Traceback (most recent call last):\n  File \"c:\\Go\\ScoutSuite\\ScoutSuite\\providers\\aws\\facade\\ec2.py\", line 121, in _get_and_set_snapshot_attributes\n    snapshot['CreateVolumePermissions'] = await run_concurrently(lambda: ec2_client.describe_snapshot_attribute(\n  File \"C:\\Python37\\lib\\concurrent\\futures\\thread.py\", line 57, in run\n    result = self.fn(*self.args, **self.kwargs)\n  File \"c:\\Go\\ScoutSuite\\ScoutSuite\\providers\\aws\\facade\\ec2.py\", line 123, in <lambda>\n    SnapshotId=snapshot['SnapshotId'])['CreateVolumePermissions'])\n  File \"C:\\Python37\\lib\\site-packages\\botocore\\client.py\", line 357, in _api_call\n    return self._make_api_call(operation_name, kwargs)\n  File \"C:\\Python37\\lib\\site-packages\\botocore\\client.py\", line 661, in _make_api_call\n    raise error_class(parsed_response, operation_name)\nbotocore.exceptions.ClientError: An error occurred (RequestLimitExceeded) when calling the DescribeSnapshotAttribute operation (reached max retries: 4): Request limit exceeded.\n"
    },
    {
        "additional_details": null,
        "exception": "Failed to describe EC2 snapshot attributes: An error occurred (RequestLimitExceeded) when calling the DescribeSnapshotAttribute operation (reached max retries: 4): Request limit exceeded.",
        "file": "ec2.py",
        "line": 121,
        "traceback": "Traceback (most recent call last):\n  File \"c:\\Go\\ScoutSuite\\ScoutSuite\\providers\\aws\\facade\\ec2.py\", line 121, in _get_and_set_snapshot_attributes\n    snapshot['CreateVolumePermissions'] = await run_concurrently(lambda: ec2_client.describe_snapshot_attribute(\n  File \"C:\\Python37\\lib\\concurrent\\futures\\thread.py\", line 57, in run\n    result = self.fn(*self.args, **self.kwargs)\n  File \"c:\\Go\\ScoutSuite\\ScoutSuite\\providers\\aws\\facade\\ec2.py\", line 123, in <lambda>\n    SnapshotId=snapshot['SnapshotId'])['CreateVolumePermissions'])\n  File \"C:\\Python37\\lib\\site-packages\\botocore\\client.py\", line 357, in _api_call\n    return self._make_api_call(operation_name, kwargs)\n  File \"C:\\Python37\\lib\\site-packages\\botocore\\client.py\", line 661, in _make_api_call\n    raise error_class(parsed_response, operation_name)\nbotocore.exceptions.ClientError: An error occurred (RequestLimitExceeded) when calling the DescribeSnapshotAttribute operation (reached max retries: 4): Request limit exceeded.\n"
    },
    {
        "additional_details": null,
        "exception": "Failed to describe EC2 snapshot attributes: An error occurred (RequestLimitExceeded) when calling the DescribeSnapshotAttribute operation (reached max retries: 4): Request limit exceeded.",
        "file": "ec2.py",
        "line": 121,
        "traceback": "Traceback (most recent call last):\n  File \"c:\\Go\\ScoutSuite\\ScoutSuite\\providers\\aws\\facade\\ec2.py\", line 121, in _get_and_set_snapshot_attributes\n    snapshot['CreateVolumePermissions'] = await run_concurrently(lambda: ec2_client.describe_snapshot_attribute(\n  File \"C:\\Python37\\lib\\concurrent\\futures\\thread.py\", line 57, in run\n    result = self.fn(*self.args, **self.kwargs)\n  File \"c:\\Go\\ScoutSuite\\ScoutSuite\\providers\\aws\\facade\\ec2.py\", line 123, in <lambda>\n    SnapshotId=snapshot['SnapshotId'])['CreateVolumePermissions'])\n  File \"C:\\Python37\\lib\\site-packages\\botocore\\client.py\", line 357, in _api_call\n    return self._make_api_call(operation_name, kwargs)\n  File \"C:\\Python37\\lib\\site-packages\\botocore\\client.py\", line 661, in _make_api_call\n    raise error_class(parsed_response, operation_name)\nbotocore.exceptions.ClientError: An error occurred (RequestLimitExceeded) when calling the DescribeSnapshotAttribute operation (reached max retries: 4): Request limit exceeded.\n"
    },
    {
        "additional_details": null,
        "exception": "Failed to describe EC2 snapshot attributes: An error occurred (RequestLimitExceeded) when calling the DescribeSnapshotAttribute operation (reached max retries: 4): Request limit exceeded.",
        "file": "ec2.py",
        "line": 121,
        "traceback": "Traceback (most recent call last):\n  File \"c:\\Go\\ScoutSuite\\ScoutSuite\\providers\\aws\\facade\\ec2.py\", line 121, in _get_and_set_snapshot_attributes\n    snapshot['CreateVolumePermissions'] = await run_concurrently(lambda: ec2_client.describe_snapshot_attribute(\n  File \"C:\\Python37\\lib\\concurrent\\futures\\thread.py\", line 57, in run\n    result = self.fn(*self.args, **self.kwargs)\n  File \"c:\\Go\\ScoutSuite\\ScoutSuite\\providers\\aws\\facade\\ec2.py\", line 123, in <lambda>\n    SnapshotId=snapshot['SnapshotId'])['CreateVolumePermissions'])\n  File \"C:\\Python37\\lib\\site-packages\\botocore\\client.py\", line 357, in _api_call\n    return self._make_api_call(operation_name, kwargs)\n  File \"C:\\Python37\\lib\\site-packages\\botocore\\client.py\", line 661, in _make_api_call\n    raise error_class(parsed_response, operation_name)\nbotocore.exceptions.ClientError: An error occurred (RequestLimitExceeded) when calling the DescribeSnapshotAttribute operation (reached max retries: 4): Request limit exceeded.\n"
    },
    {
        "additional_details": null,
        "exception": "Failed to describe EC2 snapshot attributes: An error occurred (RequestLimitExceeded) when calling the DescribeSnapshotAttribute operation (reached max retries: 4): Request limit exceeded.",
        "file": "ec2.py",
        "line": 121,
        "traceback": "Traceback (most recent call last):\n  File \"c:\\Go\\ScoutSuite\\ScoutSuite\\providers\\aws\\facade\\ec2.py\", line 121, in _get_and_set_snapshot_attributes\n    snapshot['CreateVolumePermissions'] = await run_concurrently(lambda: ec2_client.describe_snapshot_attribute(\n  File \"C:\\Python37\\lib\\concurrent\\futures\\thread.py\", line 57, in run\n    result = self.fn(*self.args, **self.kwargs)\n  File \"c:\\Go\\ScoutSuite\\ScoutSuite\\providers\\aws\\facade\\ec2.py\", line 123, in <lambda>\n    SnapshotId=snapshot['SnapshotId'])['CreateVolumePermissions'])\n  File \"C:\\Python37\\lib\\site-packages\\botocore\\client.py\", line 357, in _api_call\n    return self._make_api_call(operation_name, kwargs)\n  File \"C:\\Python37\\lib\\site-packages\\botocore\\client.py\", line 661, in _make_api_call\n    raise error_class(parsed_response, operation_name)\nbotocore.exceptions.ClientError: An error occurred (RequestLimitExceeded) when calling the DescribeSnapshotAttribute operation (reached max retries: 4): Request limit exceeded.\n"
    },
    {
        "additional_details": null,
        "exception": "Failed to get web hosting configuration for config-bucket-845286826995: An error occurred (AccessDenied) when calling the GetBucketWebsite operation: Access Denied",
        "file": "s3.py",
        "line": 86,
        "traceback": "Traceback (most recent call last):\n  File \"c:\\Go\\ScoutSuite\\ScoutSuite\\providers\\aws\\facade\\s3.py\", line 86, in _get_and_set_s3_bucket_webhosting\n    result = await run_concurrently(lambda: client.get_bucket_website(Bucket=bucket['Name']))\n  File \"C:\\Python37\\lib\\concurrent\\futures\\thread.py\", line 57, in run\n    result = self.fn(*self.args, **self.kwargs)\n  File \"c:\\Go\\ScoutSuite\\ScoutSuite\\providers\\aws\\facade\\s3.py\", line 86, in <lambda>\n    result = await run_concurrently(lambda: client.get_bucket_website(Bucket=bucket['Name']))\n  File \"C:\\Python37\\lib\\site-packages\\botocore\\client.py\", line 357, in _api_call\n    return self._make_api_call(operation_name, kwargs)\n  File \"C:\\Python37\\lib\\site-packages\\botocore\\client.py\", line 661, in _make_api_call\n    raise error_class(parsed_response, operation_name)\nbotocore.exceptions.ClientError: An error occurred (AccessDenied) when calling the GetBucketWebsite operation: Access Denied\n"
    },
    {
        "additional_details": null,
        "exception": "Failed to get versioning configuration for config-bucket-845286826995: An error occurred (AccessDenied) when calling the GetBucketVersioning operation: Access Denied",
        "file": "s3.py",
        "line": 75,
        "traceback": "Traceback (most recent call last):\n  File \"c:\\Go\\ScoutSuite\\ScoutSuite\\providers\\aws\\facade\\s3.py\", line 75, in _get_and_set_s3_bucket_versioning\n    versioning = await run_concurrently(lambda: client.get_bucket_versioning(Bucket=bucket['Name']))\n  File \"C:\\Python37\\lib\\concurrent\\futures\\thread.py\", line 57, in run\n    result = self.fn(*self.args, **self.kwargs)\n  File \"c:\\Go\\ScoutSuite\\ScoutSuite\\providers\\aws\\facade\\s3.py\", line 75, in <lambda>\n    versioning = await run_concurrently(lambda: client.get_bucket_versioning(Bucket=bucket['Name']))\n  File \"C:\\Python37\\lib\\site-packages\\botocore\\client.py\", line 357, in _api_call\n    return self._make_api_call(operation_name, kwargs)\n  File \"C:\\Python37\\lib\\site-packages\\botocore\\client.py\", line 661, in _make_api_call\n    raise error_class(parsed_response, operation_name)\nbotocore.exceptions.ClientError: An error occurred (AccessDenied) when calling the GetBucketVersioning operation: Access Denied\n"
    },
    {
        "additional_details": null,
        "exception": "Failed to get logging configuration for config-bucket-845286826995: An error occurred (AccessDenied) when calling the GetBucketLogging operation: Access Denied",
        "file": "s3.py",
        "line": 61,
        "traceback": "Traceback (most recent call last):\n  File \"c:\\Go\\ScoutSuite\\ScoutSuite\\providers\\aws\\facade\\s3.py\", line 61, in _get_and_set_s3_bucket_logging\n    logging = await run_concurrently(lambda: client.get_bucket_logging(Bucket=bucket['Name']))\n  File \"C:\\Python37\\lib\\concurrent\\futures\\thread.py\", line 57, in run\n    result = self.fn(*self.args, **self.kwargs)\n  File \"c:\\Go\\ScoutSuite\\ScoutSuite\\providers\\aws\\facade\\s3.py\", line 61, in <lambda>\n    logging = await run_concurrently(lambda: client.get_bucket_logging(Bucket=bucket['Name']))\n  File \"C:\\Python37\\lib\\site-packages\\botocore\\client.py\", line 357, in _api_call\n    return self._make_api_call(operation_name, kwargs)\n  File \"C:\\Python37\\lib\\site-packages\\botocore\\client.py\", line 661, in _make_api_call\n    raise error_class(parsed_response, operation_name)\nbotocore.exceptions.ClientError: An error occurred (AccessDenied) when calling the GetBucketLogging operation: Access Denied\n"
    },
    {
        "additional_details": null,
        "exception": "Failed to get encryption configuration for config-bucket-845286826995: An error occurred (AccessDenied) when calling the GetBucketEncryption operation: Access Denied",
        "file": "s3.py",
        "line": 98,
        "traceback": "Traceback (most recent call last):\n  File \"c:\\Go\\ScoutSuite\\ScoutSuite\\providers\\aws\\facade\\s3.py\", line 98, in _get_and_set_s3_bucket_default_encryption\n    await run_concurrently(lambda: client.get_bucket_encryption(Bucket=bucket['Name']))\n  File \"C:\\Python37\\lib\\concurrent\\futures\\thread.py\", line 57, in run\n    result = self.fn(*self.args, **self.kwargs)\n  File \"c:\\Go\\ScoutSuite\\ScoutSuite\\providers\\aws\\facade\\s3.py\", line 98, in <lambda>\n    await run_concurrently(lambda: client.get_bucket_encryption(Bucket=bucket['Name']))\n  File \"C:\\Python37\\lib\\site-packages\\botocore\\client.py\", line 357, in _api_call\n    return self._make_api_call(operation_name, kwargs)\n  File \"C:\\Python37\\lib\\site-packages\\botocore\\client.py\", line 661, in _make_api_call\n    raise error_class(parsed_response, operation_name)\nbotocore.exceptions.ClientError: An error occurred (AccessDenied) when calling the GetBucketEncryption operation: Access Denied\n"
    },
    {
        "additional_details": null,
        "exception": "Failed to get ACL configuration for config-bucket-845286826995: An error occurred (AccessDenied) when calling the GetBucketAcl operation: Access Denied",
        "file": "s3.py",
        "line": 118,
        "traceback": "Traceback (most recent call last):\n  File \"c:\\Go\\ScoutSuite\\ScoutSuite\\providers\\aws\\facade\\s3.py\", line 118, in _get_and_set_s3_acls\n    grants = await run_concurrently(lambda: client.get_bucket_acl(Bucket=bucket_name))\n  File \"C:\\Python37\\lib\\concurrent\\futures\\thread.py\", line 57, in run\n    result = self.fn(*self.args, **self.kwargs)\n  File \"c:\\Go\\ScoutSuite\\ScoutSuite\\providers\\aws\\facade\\s3.py\", line 118, in <lambda>\n    grants = await run_concurrently(lambda: client.get_bucket_acl(Bucket=bucket_name))\n  File \"C:\\Python37\\lib\\site-packages\\botocore\\client.py\", line 357, in _api_call\n    return self._make_api_call(operation_name, kwargs)\n  File \"C:\\Python37\\lib\\site-packages\\botocore\\client.py\", line 661, in _make_api_call\n    raise error_class(parsed_response, operation_name)\nbotocore.exceptions.ClientError: An error occurred (AccessDenied) when calling the GetBucketAcl operation: Access Denied\n"
    },
    {
        "additional_details": null,
        "exception": "Failed to get bucket policy for config-bucket-845286826995: An error occurred (AccessDenied) when calling the GetBucketPolicy operation: Access Denied",
        "file": "s3.py",
        "line": 144,
        "traceback": "Traceback (most recent call last):\n  File \"c:\\Go\\ScoutSuite\\ScoutSuite\\providers\\aws\\facade\\s3.py\", line 144, in _get_and_set_s3_bucket_policy\n    bucket_policy = await run_concurrently(lambda: client.get_bucket_policy(Bucket=bucket['Name']))\n  File \"C:\\Python37\\lib\\concurrent\\futures\\thread.py\", line 57, in run\n    result = self.fn(*self.args, **self.kwargs)\n  File \"c:\\Go\\ScoutSuite\\ScoutSuite\\providers\\aws\\facade\\s3.py\", line 144, in <lambda>\n    bucket_policy = await run_concurrently(lambda: client.get_bucket_policy(Bucket=bucket['Name']))\n  File \"C:\\Python37\\lib\\site-packages\\botocore\\client.py\", line 357, in _api_call\n    return self._make_api_call(operation_name, kwargs)\n  File \"C:\\Python37\\lib\\site-packages\\botocore\\client.py\", line 661, in _make_api_call\n    raise error_class(parsed_response, operation_name)\nbotocore.exceptions.ClientError: An error occurred (AccessDenied) when calling the GetBucketPolicy operation: Access Denied\n"
    },
    {
        "additional_details": null,
        "exception": "Failed to get Config recorder statuses: An error occurred (UnrecognizedClientException) when calling the DescribeConfigurationRecorderStatus operation: The security token included in the request is invalid.",
        "file": "config.py",
        "line": 24,
        "traceback": "Traceback (most recent call last):\n  File \"c:\\Go\\ScoutSuite\\ScoutSuite\\providers\\aws\\facade\\config.py\", line 24, in get_recorders\n    (await run_concurrently(client.describe_configuration_recorder_status))['ConfigurationRecordersStatus']\n  File \"C:\\Python37\\lib\\concurrent\\futures\\thread.py\", line 57, in run\n    result = self.fn(*self.args, **self.kwargs)\n  File \"C:\\Python37\\lib\\site-packages\\botocore\\client.py\", line 357, in _api_call\n    return self._make_api_call(operation_name, kwargs)\n  File \"C:\\Python37\\lib\\site-packages\\botocore\\client.py\", line 661, in _make_api_call\n    raise error_class(parsed_response, operation_name)\nbotocore.exceptions.ClientError: An error occurred (UnrecognizedClientException) when calling the DescribeConfigurationRecorderStatus operation: The security token included in the request is invalid.\n"
    },
    {
        "additional_details": null,
        "exception": "Failed to describe EC2 snapshot attributes: An error occurred (RequestLimitExceeded) when calling the DescribeSnapshotAttribute operation (reached max retries: 4): Request limit exceeded.",
        "file": "ec2.py",
        "line": 121,
        "traceback": "Traceback (most recent call last):\n  File \"c:\\Go\\ScoutSuite\\ScoutSuite\\providers\\aws\\facade\\ec2.py\", line 121, in _get_and_set_snapshot_attributes\n    snapshot['CreateVolumePermissions'] = await run_concurrently(lambda: ec2_client.describe_snapshot_attribute(\n  File \"C:\\Python37\\lib\\concurrent\\futures\\thread.py\", line 57, in run\n    result = self.fn(*self.args, **self.kwargs)\n  File \"c:\\Go\\ScoutSuite\\ScoutSuite\\providers\\aws\\facade\\ec2.py\", line 123, in <lambda>\n    SnapshotId=snapshot['SnapshotId'])['CreateVolumePermissions'])\n  File \"C:\\Python37\\lib\\site-packages\\botocore\\client.py\", line 357, in _api_call\n    return self._make_api_call(operation_name, kwargs)\n  File \"C:\\Python37\\lib\\site-packages\\botocore\\client.py\", line 661, in _make_api_call\n    raise error_class(parsed_response, operation_name)\nbotocore.exceptions.ClientError: An error occurred (RequestLimitExceeded) when calling the DescribeSnapshotAttribute operation (reached max retries: 4): Request limit exceeded.\n"
    },
    {
        "additional_details": null,
        "exception": "Failed to describe EC2 snapshot attributes: An error occurred (RequestLimitExceeded) when calling the DescribeSnapshotAttribute operation (reached max retries: 4): Request limit exceeded.",
        "file": "ec2.py",
        "line": 121,
        "traceback": "Traceback (most recent call last):\n  File \"c:\\Go\\ScoutSuite\\ScoutSuite\\providers\\aws\\facade\\ec2.py\", line 121, in _get_and_set_snapshot_attributes\n    snapshot['CreateVolumePermissions'] = await run_concurrently(lambda: ec2_client.describe_snapshot_attribute(\n  File \"C:\\Python37\\lib\\concurrent\\futures\\thread.py\", line 57, in run\n    result = self.fn(*self.args, **self.kwargs)\n  File \"c:\\Go\\ScoutSuite\\ScoutSuite\\providers\\aws\\facade\\ec2.py\", line 123, in <lambda>\n    SnapshotId=snapshot['SnapshotId'])['CreateVolumePermissions'])\n  File \"C:\\Python37\\lib\\site-packages\\botocore\\client.py\", line 357, in _api_call\n    return self._make_api_call(operation_name, kwargs)\n  File \"C:\\Python37\\lib\\site-packages\\botocore\\client.py\", line 661, in _make_api_call\n    raise error_class(parsed_response, operation_name)\nbotocore.exceptions.ClientError: An error occurred (RequestLimitExceeded) when calling the DescribeSnapshotAttribute operation (reached max retries: 4): Request limit exceeded.\n"
    }
]
